{
 "cells": [
  {
   "cell_type": "markdown",
   "metadata": {
    "toc": true
   },
   "source": [
    "<h1>Table of Contents<span class=\"tocSkip\"></span></h1>\n",
    "<div class=\"toc\"><ul class=\"toc-item\"></ul></div>"
   ]
  },
  {
   "cell_type": "code",
   "execution_count": 11,
   "metadata": {},
   "outputs": [
    {
     "name": "stdout",
     "output_type": "stream",
     "text": [
      "The rpy2.ipython extension is already loaded. To reload it, use:\n",
      "  %reload_ext rpy2.ipython\n",
      "The rmagic extension is already loaded. To reload it, use:\n",
      "  %reload_ext rmagic\n"
     ]
    }
   ],
   "source": [
    "%run \"../../xUtilz/utilz_only_loader.ipynb\""
   ]
  },
  {
   "cell_type": "code",
   "execution_count": 12,
   "metadata": {},
   "outputs": [],
   "source": [
    "db = pd.read_csv( \"../../datasets/LG/IN/181109_Referral_Reasons.csv\" )\n",
    "\n",
    "db[\"CHV Name\"] = \"CHV \" +  pd.Series( pd.factorize( db[\"CHV Name\"])[0] + 1).astype( str)\n",
    "db[\"Patient Name\"] = \"Patient \" +  pd.Series( pd.factorize( db[\"Patient Name\"])[0] + 1).astype( str)\n",
    "db.drop( \"CHV Phone\", axis=1, inplace=True)\n",
    "\n",
    "var_Category_Referral_Reason = \"Category Referral Reason\"\n",
    "var_Unsupported = \"Unsupported Cases\"\n",
    "var_HIVST = \"HIVST\"\n",
    "var_Display_Colz = [\"Date of referral\", \"CHV Name\", \"Patient Name\" ,\"Referral Reason\", \"Reason for Referral\"]\n",
    "\n",
    "\n",
    "reasons_groupz = { \n",
    "    \"Neonates\" : [ \"months\", \"umbilical\", \"umbllical\"], \n",
    "    \"Pregnancy\" : [\"delivery\"], \n",
    "    \"U5 Danger Signs\" : [ \"Danger\", \"Diarrhoea\", \"Diarrhea\", \"Dairrhea\", \"Coughing\", \"Cough\", \"Fever\",\"Pneumonia\", \"Pnuemonia\",\n",
    "                        \"Pheumonia\", ],\n",
    "    \"HIVST\" : [\"reactive\", \"partner\", \"intimate\"], \n",
    "    \"Unsupported Cases\" : []\n",
    "}\n",
    "\n",
    "db[ var_Category_Referral_Reason ] = db[\"Referral Reason\"].apply( lambda x: searchString(x, reasons_groupz) ) \n",
    "\n",
    "# 1. set Date of referral to a datetime type \n",
    "db[\"Date of referral\"] = pd.to_datetime( db[\"Date of referral\"], format=\"%d-%b-%y\") # inplace=True)\n",
    "\n",
    "# 2. Extract Month and year categories \n",
    "db[\"Year\"] = db[\"Date of referral\"].dt.year \n",
    "db[\"Month\"] = db[\"Date of referral\"].dt.strftime('%b-%y') \n",
    "db[\"Day_of_Week\"] = db[\"Date of referral\"].dt.weekday_name.str[:3] \n",
    "\n",
    "db.sort_values( by='Date of referral', inplace=True)\n",
    "\n",
    "LAST_UPDATED = db[\"Date of referral\"].max().strftime( '%d-%b-%Y')"
   ]
  },
  {
   "cell_type": "code",
   "execution_count": 30,
   "metadata": {
    "scrolled": true
   },
   "outputs": [
    {
     "data": {
      "text/plain": [
       "['All',\n",
       " 'Unsupported Cases',\n",
       " 'U5 Danger Signs',\n",
       " 'Pregnancy',\n",
       " 'No Response',\n",
       " 'Neonates',\n",
       " 'HIVST']"
      ]
     },
     "execution_count": 30,
     "metadata": {},
     "output_type": "execute_result"
    }
   ],
   "source": [
    "varALLPlaceholder = \"All\"\n",
    "var_FilterOptions = [ varALLPlaceholder ]+db[\"Category Referral Reason\"].unique().tolist()\n",
    "\n",
    "var_TableFields = [\"Date of referral\", \"CHV Name\", \"Patient Name\", \"Category Referral Reason\", \"Referral Reason\" ]\n",
    "\n",
    "var_FilterOptions\n",
    "\n",
    "#def updateDataset( x=varALLPlaceholder): \n",
    "#    return db[ db['Category Referral Reason'] == x][var_TableFields] if x != varALLPlaceholder else db[var_TableFields]\n",
    "\n",
    "#interact( updateDataset, \n",
    "#         x=[ varALLPlaceholder ]+db[\"Category Referral Reason\"].unique().tolist(), )"
   ]
  },
  {
   "cell_type": "code",
   "execution_count": 4,
   "metadata": {},
   "outputs": [],
   "source": [
    "app = dash.Dash( \"hello world\")\n",
    "app.layout = dhtml.Div(\n",
    "[\n",
    "    dcc.Dropdown(\n",
    "        id='referral_cats',\n",
    "        options = var_FilterOptions,\n",
    "        value = varALLPlaceholder\n",
    "    ),\n",
    "    dcc.Graph( id='dbTable')\n",
    "], style={\n",
    "    'width' : '500'\n",
    "})\n",
    "\n",
    "@app.callback( Output('dbTable', 'figure'), [Input('referral_cats', 'value')])\n",
    "def updateTable( selected_value):\n",
    "    df = dweb.DataReader(\n",
    "        selected_value,\n",
    "        'google', \n",
    "        dt( 2017, 1, 1),\n",
    "        dt.now()\n",
    "    )\n",
    "    return{\n",
    "        'data': [\n",
    "            {\n",
    "                'x' : df.index,\n",
    "                'y' : df.Close\n",
    "            }\n",
    "        ],\n",
    "        'layout' : { 'margin': { 'l': 40, 'r': 0, 't': 20, 'b': 30 }}\n",
    "    }\n",
    "\n",
    "app.css.append_css({\n",
    "    'external_url': 'https://codepen.io/chriddyp/pen/bWLwgP.css'\n",
    "})\n",
    "\n",
    "#app.run_server()\n",
    "    "
   ]
  },
  {
   "cell_type": "code",
   "execution_count": 16,
   "metadata": {},
   "outputs": [
    {
     "name": "stderr",
     "output_type": "stream",
     "text": [
      " * Running on http://127.0.0.1:8050/ (Press CTRL+C to quit)\n",
      "127.0.0.1 - - [09/Nov/2018 16:51:23] \"GET / HTTP/1.1\" 200 -\n",
      "127.0.0.1 - - [09/Nov/2018 16:51:25] \"GET /_dash-layout HTTP/1.1\" 200 -\n",
      "127.0.0.1 - - [09/Nov/2018 16:51:25] \"GET /_dash-dependencies HTTP/1.1\" 200 -\n"
     ]
    }
   ],
   "source": [
    "## https://dash.plot.ly/getting-started \n",
    "\n",
    "def genTable( db, max_r=10):\n",
    "    return dhtml.Table(\n",
    "        #Header\n",
    "        [ dhtml.Tr( [ dhtml.Th( col) for col in db.columns])] + \n",
    "\n",
    "        # boddy\n",
    "        [ dhtml.Tr([\n",
    "            dhtml.Td( db.iloc[i][col]) for col in db.columns ]) for i in range( min(len(db), max_r))\n",
    "        ]\n",
    "    ) \n",
    "\n",
    "\n",
    "external_stylesheets = ['https://codepen.io/chriddyp/pen/bWLwgP.css']\n",
    "\n",
    "collors = {\n",
    "    'bg': '#111111',\n",
    "    'txt': '#7FDBFF'\n",
    "}\n",
    "\n",
    "\n",
    "app = dash.Dash( __name__, external_stylesheets=external_stylesheets)\n",
    "\n",
    "app.layout = dhtml.Div(\n",
    "style= {'backgroundColor': collors['bg'], 'textAlign': 'center', 'color': collors['txt']}, \n",
    "children=[\n",
    "    dhtml.H1( children='Hello Dash'),\n",
    "    \n",
    "    dhtml.Div( children= '''\n",
    "    Dash: A web application framework for Python\n",
    "    '''),\n",
    "    \n",
    "    dcc.Graph(\n",
    "        id='graph1',\n",
    "        figure={\n",
    "            'data' : [\n",
    "                { 'x': [ 1, 2, 3], 'y': [4, 1, 2], 'type': 'bar', 'name': 'SF'}, \n",
    "                { 'x' : [1, 2, 3], 'y': [2, 3, 5], 'type': 'bar', 'name': 'MTR'}\n",
    "            ],\n",
    "            'layout': {\n",
    "                'title': 'Dash Data Visualization'\n",
    "            }\n",
    "        }     \n",
    "    ),\n",
    "    \n",
    "    \n",
    "    dhtml.Div( [\n",
    "        dhtml.H4( \"Table Title Here\"), \n",
    "        genTable( db )\n",
    "    ]) \n",
    "])\n",
    "\n",
    "\n",
    "\n",
    "app.run_server( )"
   ]
  },
  {
   "cell_type": "code",
   "execution_count": 20,
   "metadata": {},
   "outputs": [
    {
     "name": "stderr",
     "output_type": "stream",
     "text": [
      " * Running on http://127.0.0.1:8050/ (Press CTRL+C to quit)\n",
      "127.0.0.1 - - [09/Nov/2018 17:02:05] \"GET / HTTP/1.1\" 200 -\n",
      "127.0.0.1 - - [09/Nov/2018 17:02:06] \"GET /_dash-layout HTTP/1.1\" 200 -\n",
      "127.0.0.1 - - [09/Nov/2018 17:02:06] \"GET /_dash-dependencies HTTP/1.1\" 200 -\n"
     ]
    }
   ],
   "source": [
    "import plotly.graph_objs as go \n",
    "\n",
    "df = pd.read_csv(\n",
    "    'https://gist.githubusercontent.com/chriddyp/' +\n",
    "    '5d1ea79569ed194d432e56108a04d188/raw/' +\n",
    "    'a9f9e8076b837d541398e999dcbac2b2826a81f8/'+\n",
    "    'gdp-life-exp-2007.csv')\n",
    "\n",
    "\n",
    "app = dash.Dash(__name__, external_stylesheets=external_stylesheets)\n",
    "\n",
    "app.layout = dhtml.Div([\n",
    "    dcc.Graph(\n",
    "        id='graph3',\n",
    "        figure={\n",
    "            'data': [\n",
    "                go.Scatter(\n",
    "                    x=df[df['continent'] == i ][ 'gdp per capita' ], \n",
    "                    y=df[ df['continent'] == i ][ 'life expectancy'], \n",
    "                    text=df[ df['continent']==i]['country'],\n",
    "                    mode='markers', \n",
    "                    opacity= 0.7, \n",
    "                    marker= {\n",
    "                        'size': 15,\n",
    "                        'line': { 'width': 0.5, 'color': 'white'}\n",
    "                    },\n",
    "                    name= i \n",
    "                ) for i in df. continent.unique() \n",
    "                \n",
    "            ], \n",
    "            'layout': go.Layout(\n",
    "                xaxis={'type': 'log', 'title': 'GDP Per Capita' }, \n",
    "                yaxis={ 'title': \"Life Expectancy\"}, \n",
    "                margin={ 'l': 40, 'b': 40, 't': 10, 'r': 10},\n",
    "                legend={ 'x': 0, 'y': 1},\n",
    "                hovermode= 'closest'\n",
    "            )\n",
    "        }\n",
    "    )\n",
    "])\n",
    "\n",
    "app.run_server()"
   ]
  },
  {
   "cell_type": "code",
   "execution_count": 21,
   "metadata": {},
   "outputs": [
    {
     "name": "stderr",
     "output_type": "stream",
     "text": [
      " * Running on http://127.0.0.1:8050/ (Press CTRL+C to quit)\n",
      "127.0.0.1 - - [09/Nov/2018 17:10:56] \"GET / HTTP/1.1\" 200 -\n"
     ]
    }
   ],
   "source": [
    "## And Now in Markdown instead of html_components\n",
    "app = dash.Dash(__name__, external_stylesheets=external_stylesheets)\n",
    "\n",
    "markdwon_text = '''\n",
    "### Dash and Markdown\n",
    "\n",
    "The quick brown fox jumped over the lazy dogs. \n",
    "\n",
    "Something something [that links here](http://www.google.com)\n",
    "\n",
    "And some listing too\n",
    "1. quick  \n",
    "2. brown \n",
    "3. lazy \n",
    "\n",
    "'''\n",
    "\n",
    "app.layout = dhtml.Div([\n",
    "    dcc.Markdown( children=markdwon_text)\n",
    "])\n",
    "\n",
    "app.run_server()"
   ]
  },
  {
   "cell_type": "code",
   "execution_count": 37,
   "metadata": {},
   "outputs": [
    {
     "name": "stderr",
     "output_type": "stream",
     "text": [
      " * Running on http://127.0.0.1:8050/ (Press CTRL+C to quit)\n",
      "127.0.0.1 - - [09/Nov/2018 17:26:20] \"GET / HTTP/1.1\" 200 -\n",
      "127.0.0.1 - - [09/Nov/2018 17:26:23] \"GET /_dash-layout HTTP/1.1\" 200 -\n",
      "127.0.0.1 - - [09/Nov/2018 17:26:23] \"GET /_dash-dependencies HTTP/1.1\" 200 -\n"
     ]
    }
   ],
   "source": [
    "## Components << Not showing list options + check box is selecting everything\n",
    "\n",
    "app = dash.Dash(__name__, external_stylesheets=external_stylesheets)\n",
    "\n",
    "app.layout = dhtml.Div([\n",
    "    dhtml.Label('DropDown'),\n",
    "    dcc.Dropdown(\n",
    "        options = var_FilterOptions,\n",
    "        value = varALLPlaceholder\n",
    "    ),\n",
    "    \n",
    "    dhtml.Label( \"Multi-Select Dropdown\"),\n",
    "    dcc.Dropdown(\n",
    "        options = { 'label': \"NYC\"},\n",
    "        value = varALLPlaceholder,\n",
    "        multi=True\n",
    "    ),\n",
    "    \n",
    "    dhtml.Label('Radio Items'),\n",
    "    dcc.RadioItems(\n",
    "        options=[\n",
    "            {'label': 'New York City', 'value': 'NYC'},\n",
    "            {'label': u'Montréal', 'value': 'MTL'},\n",
    "            {'label': 'San Francisco', 'value': 'SF'}\n",
    "        ],\n",
    "        value='MTL'\n",
    "    ),\n",
    "    \n",
    "    dhtml.Label( \"Checkboxes\"),\n",
    "    dcc.Checklist(\n",
    "        options = var_FilterOptions + [\n",
    "            {'label': 'New York City', 'value': 'NYC'},\n",
    "            {'label': u'Montréal', 'value': 'MTL'},\n",
    "            {'label': 'San Francisco', 'value': 'SF'} ], \n",
    "        values = [varALLPlaceholder, \"HIVST\"] \n",
    "    ),\n",
    "    \n",
    "    \n",
    "    dhtml.Label( \"Text Input\"),\n",
    "    dcc.Input(\n",
    "        type='text',\n",
    "        value = varALLPlaceholder,\n",
    "    ),\n",
    "    \n",
    "    \n",
    "    dhtml.Label( \"Slider\"),\n",
    "    dcc.Slider(\n",
    "        min=0,\n",
    "        max=9,\n",
    "        marks={ i: 'Label {}'.format(i) if i == 1 else str(i) for i in range(1,6 )}, \n",
    "        value=5\n",
    "    )\n",
    "], style={ 'columnCount': 2})\n",
    "\n",
    "app.run_server()"
   ]
  },
  {
   "cell_type": "code",
   "execution_count": 41,
   "metadata": {},
   "outputs": [
    {
     "name": "stderr",
     "output_type": "stream",
     "text": [
      " * Running on http://127.0.0.1:8050/ (Press CTRL+C to quit)\n",
      "[2018-11-09 17:36:00,287] ERROR in app: Exception on /_dash-update-component [POST]\n",
      "Traceback (most recent call last):\n",
      "  File \"C:\\Users\\BILHA\\Anaconda3\\lib\\site-packages\\flask\\app.py\", line 1982, in wsgi_app\n",
      "    response = self.full_dispatch_request()\n",
      "  File \"C:\\Users\\BILHA\\Anaconda3\\lib\\site-packages\\flask\\app.py\", line 1614, in full_dispatch_request\n",
      "    rv = self.handle_user_exception(e)\n",
      "  File \"C:\\Users\\BILHA\\Anaconda3\\lib\\site-packages\\flask\\app.py\", line 1517, in handle_user_exception\n",
      "    reraise(exc_type, exc_value, tb)\n",
      "  File \"C:\\Users\\BILHA\\Anaconda3\\lib\\site-packages\\flask\\_compat.py\", line 33, in reraise\n",
      "    raise value\n",
      "  File \"C:\\Users\\BILHA\\Anaconda3\\lib\\site-packages\\flask\\app.py\", line 1612, in full_dispatch_request\n",
      "    rv = self.dispatch_request()\n",
      "  File \"C:\\Users\\BILHA\\Anaconda3\\lib\\site-packages\\flask\\app.py\", line 1598, in dispatch_request\n",
      "    return self.view_functions[rule.endpoint](**req.view_args)\n",
      "  File \"C:\\Users\\BILHA\\Anaconda3\\lib\\site-packages\\dash\\dash.py\", line 915, in dispatch\n",
      "    return self.callback_map[target_id]['callback'](*args)\n",
      "  File \"C:\\Users\\BILHA\\Anaconda3\\lib\\site-packages\\dash\\dash.py\", line 855, in add_context\n",
      "    output_value = func(*args, **kwargs)\n",
      "  File \"<ipython-input-41-d549e6c83915>\", line 15, in update_output_div\n",
      "    return 'You entered \"{ }\"'.format( input_value)\n",
      "KeyError: ' '\n",
      "127.0.0.1 - - [09/Nov/2018 17:36:00] \"POST /_dash-update-component HTTP/1.1\" 500 -\n",
      "127.0.0.1 - - [09/Nov/2018 17:36:00] \"GET / HTTP/1.1\" 200 -\n",
      "127.0.0.1 - - [09/Nov/2018 17:36:02] \"GET /_dash-layout HTTP/1.1\" 200 -\n",
      "127.0.0.1 - - [09/Nov/2018 17:36:02] \"GET /_dash-dependencies HTTP/1.1\" 200 -\n",
      "[2018-11-09 17:36:02,846] ERROR in app: Exception on /_dash-update-component [POST]\n",
      "Traceback (most recent call last):\n",
      "  File \"C:\\Users\\BILHA\\Anaconda3\\lib\\site-packages\\flask\\app.py\", line 1982, in wsgi_app\n",
      "    response = self.full_dispatch_request()\n",
      "  File \"C:\\Users\\BILHA\\Anaconda3\\lib\\site-packages\\flask\\app.py\", line 1614, in full_dispatch_request\n",
      "    rv = self.handle_user_exception(e)\n",
      "  File \"C:\\Users\\BILHA\\Anaconda3\\lib\\site-packages\\flask\\app.py\", line 1517, in handle_user_exception\n",
      "    reraise(exc_type, exc_value, tb)\n",
      "  File \"C:\\Users\\BILHA\\Anaconda3\\lib\\site-packages\\flask\\_compat.py\", line 33, in reraise\n",
      "    raise value\n",
      "  File \"C:\\Users\\BILHA\\Anaconda3\\lib\\site-packages\\flask\\app.py\", line 1612, in full_dispatch_request\n",
      "    rv = self.dispatch_request()\n",
      "  File \"C:\\Users\\BILHA\\Anaconda3\\lib\\site-packages\\flask\\app.py\", line 1598, in dispatch_request\n",
      "    return self.view_functions[rule.endpoint](**req.view_args)\n",
      "  File \"C:\\Users\\BILHA\\Anaconda3\\lib\\site-packages\\dash\\dash.py\", line 915, in dispatch\n",
      "    return self.callback_map[target_id]['callback'](*args)\n",
      "  File \"C:\\Users\\BILHA\\Anaconda3\\lib\\site-packages\\dash\\dash.py\", line 855, in add_context\n",
      "    output_value = func(*args, **kwargs)\n",
      "  File \"<ipython-input-41-d549e6c83915>\", line 15, in update_output_div\n",
      "    return 'You entered \"{ }\"'.format( input_value)\n",
      "KeyError: ' '\n",
      "127.0.0.1 - - [09/Nov/2018 17:36:02] \"POST /_dash-update-component HTTP/1.1\" 500 -\n",
      "[2018-11-09 17:36:04,603] ERROR in app: Exception on /_dash-update-component [POST]\n",
      "Traceback (most recent call last):\n",
      "  File \"C:\\Users\\BILHA\\Anaconda3\\lib\\site-packages\\flask\\app.py\", line 1982, in wsgi_app\n",
      "    response = self.full_dispatch_request()\n",
      "  File \"C:\\Users\\BILHA\\Anaconda3\\lib\\site-packages\\flask\\app.py\", line 1614, in full_dispatch_request\n",
      "    rv = self.handle_user_exception(e)\n",
      "  File \"C:\\Users\\BILHA\\Anaconda3\\lib\\site-packages\\flask\\app.py\", line 1517, in handle_user_exception\n",
      "    reraise(exc_type, exc_value, tb)\n",
      "  File \"C:\\Users\\BILHA\\Anaconda3\\lib\\site-packages\\flask\\_compat.py\", line 33, in reraise\n",
      "    raise value\n",
      "  File \"C:\\Users\\BILHA\\Anaconda3\\lib\\site-packages\\flask\\app.py\", line 1612, in full_dispatch_request\n",
      "    rv = self.dispatch_request()\n",
      "  File \"C:\\Users\\BILHA\\Anaconda3\\lib\\site-packages\\flask\\app.py\", line 1598, in dispatch_request\n",
      "    return self.view_functions[rule.endpoint](**req.view_args)\n",
      "  File \"C:\\Users\\BILHA\\Anaconda3\\lib\\site-packages\\dash\\dash.py\", line 915, in dispatch\n",
      "    return self.callback_map[target_id]['callback'](*args)\n",
      "  File \"C:\\Users\\BILHA\\Anaconda3\\lib\\site-packages\\dash\\dash.py\", line 855, in add_context\n",
      "    output_value = func(*args, **kwargs)\n",
      "  File \"<ipython-input-41-d549e6c83915>\", line 15, in update_output_div\n",
      "    return 'You entered \"{ }\"'.format( input_value)\n",
      "KeyError: ' '\n",
      "127.0.0.1 - - [09/Nov/2018 17:36:04] \"POST /_dash-update-component HTTP/1.1\" 500 -\n",
      "[2018-11-09 17:36:04,917] ERROR in app: Exception on /_dash-update-component [POST]\n",
      "Traceback (most recent call last):\n",
      "  File \"C:\\Users\\BILHA\\Anaconda3\\lib\\site-packages\\flask\\app.py\", line 1982, in wsgi_app\n",
      "    response = self.full_dispatch_request()\n",
      "  File \"C:\\Users\\BILHA\\Anaconda3\\lib\\site-packages\\flask\\app.py\", line 1614, in full_dispatch_request\n",
      "    rv = self.handle_user_exception(e)\n",
      "  File \"C:\\Users\\BILHA\\Anaconda3\\lib\\site-packages\\flask\\app.py\", line 1517, in handle_user_exception\n",
      "    reraise(exc_type, exc_value, tb)\n",
      "  File \"C:\\Users\\BILHA\\Anaconda3\\lib\\site-packages\\flask\\_compat.py\", line 33, in reraise\n",
      "    raise value\n",
      "  File \"C:\\Users\\BILHA\\Anaconda3\\lib\\site-packages\\flask\\app.py\", line 1612, in full_dispatch_request\n",
      "    rv = self.dispatch_request()\n",
      "  File \"C:\\Users\\BILHA\\Anaconda3\\lib\\site-packages\\flask\\app.py\", line 1598, in dispatch_request\n",
      "    return self.view_functions[rule.endpoint](**req.view_args)\n",
      "  File \"C:\\Users\\BILHA\\Anaconda3\\lib\\site-packages\\dash\\dash.py\", line 915, in dispatch\n",
      "    return self.callback_map[target_id]['callback'](*args)\n",
      "  File \"C:\\Users\\BILHA\\Anaconda3\\lib\\site-packages\\dash\\dash.py\", line 855, in add_context\n",
      "    output_value = func(*args, **kwargs)\n",
      "  File \"<ipython-input-41-d549e6c83915>\", line 15, in update_output_div\n",
      "    return 'You entered \"{ }\"'.format( input_value)\n",
      "KeyError: ' '\n",
      "127.0.0.1 - - [09/Nov/2018 17:36:04] \"POST /_dash-update-component HTTP/1.1\" 500 -\n",
      "[2018-11-09 17:36:05,041] ERROR in app: Exception on /_dash-update-component [POST]\n",
      "Traceback (most recent call last):\n",
      "  File \"C:\\Users\\BILHA\\Anaconda3\\lib\\site-packages\\flask\\app.py\", line 1982, in wsgi_app\n",
      "    response = self.full_dispatch_request()\n",
      "  File \"C:\\Users\\BILHA\\Anaconda3\\lib\\site-packages\\flask\\app.py\", line 1614, in full_dispatch_request\n",
      "    rv = self.handle_user_exception(e)\n",
      "  File \"C:\\Users\\BILHA\\Anaconda3\\lib\\site-packages\\flask\\app.py\", line 1517, in handle_user_exception\n",
      "    reraise(exc_type, exc_value, tb)\n",
      "  File \"C:\\Users\\BILHA\\Anaconda3\\lib\\site-packages\\flask\\_compat.py\", line 33, in reraise\n",
      "    raise value\n",
      "  File \"C:\\Users\\BILHA\\Anaconda3\\lib\\site-packages\\flask\\app.py\", line 1612, in full_dispatch_request\n",
      "    rv = self.dispatch_request()\n",
      "  File \"C:\\Users\\BILHA\\Anaconda3\\lib\\site-packages\\flask\\app.py\", line 1598, in dispatch_request\n",
      "    return self.view_functions[rule.endpoint](**req.view_args)\n",
      "  File \"C:\\Users\\BILHA\\Anaconda3\\lib\\site-packages\\dash\\dash.py\", line 915, in dispatch\n",
      "    return self.callback_map[target_id]['callback'](*args)\n",
      "  File \"C:\\Users\\BILHA\\Anaconda3\\lib\\site-packages\\dash\\dash.py\", line 855, in add_context\n",
      "    output_value = func(*args, **kwargs)\n",
      "  File \"<ipython-input-41-d549e6c83915>\", line 15, in update_output_div\n",
      "    return 'You entered \"{ }\"'.format( input_value)\n",
      "KeyError: ' '\n",
      "127.0.0.1 - - [09/Nov/2018 17:36:05] \"POST /_dash-update-component HTTP/1.1\" 500 -\n",
      "[2018-11-09 17:36:05,105] ERROR in app: Exception on /_dash-update-component [POST]\n",
      "Traceback (most recent call last):\n",
      "  File \"C:\\Users\\BILHA\\Anaconda3\\lib\\site-packages\\flask\\app.py\", line 1982, in wsgi_app\n",
      "    response = self.full_dispatch_request()\n",
      "  File \"C:\\Users\\BILHA\\Anaconda3\\lib\\site-packages\\flask\\app.py\", line 1614, in full_dispatch_request\n",
      "    rv = self.handle_user_exception(e)\n",
      "  File \"C:\\Users\\BILHA\\Anaconda3\\lib\\site-packages\\flask\\app.py\", line 1517, in handle_user_exception\n",
      "    reraise(exc_type, exc_value, tb)\n",
      "  File \"C:\\Users\\BILHA\\Anaconda3\\lib\\site-packages\\flask\\_compat.py\", line 33, in reraise\n",
      "    raise value\n",
      "  File \"C:\\Users\\BILHA\\Anaconda3\\lib\\site-packages\\flask\\app.py\", line 1612, in full_dispatch_request\n",
      "    rv = self.dispatch_request()\n",
      "  File \"C:\\Users\\BILHA\\Anaconda3\\lib\\site-packages\\flask\\app.py\", line 1598, in dispatch_request\n",
      "    return self.view_functions[rule.endpoint](**req.view_args)\n",
      "  File \"C:\\Users\\BILHA\\Anaconda3\\lib\\site-packages\\dash\\dash.py\", line 915, in dispatch\n",
      "    return self.callback_map[target_id]['callback'](*args)\n",
      "  File \"C:\\Users\\BILHA\\Anaconda3\\lib\\site-packages\\dash\\dash.py\", line 855, in add_context\n",
      "    output_value = func(*args, **kwargs)\n",
      "  File \"<ipython-input-41-d549e6c83915>\", line 15, in update_output_div\n",
      "    return 'You entered \"{ }\"'.format( input_value)\n",
      "KeyError: ' '\n"
     ]
    },
    {
     "name": "stderr",
     "output_type": "stream",
     "text": [
      "127.0.0.1 - - [09/Nov/2018 17:36:05] \"POST /_dash-update-component HTTP/1.1\" 500 -\n",
      "[2018-11-09 17:36:05,301] ERROR in app: Exception on /_dash-update-component [POST]\n",
      "Traceback (most recent call last):\n",
      "  File \"C:\\Users\\BILHA\\Anaconda3\\lib\\site-packages\\flask\\app.py\", line 1982, in wsgi_app\n",
      "    response = self.full_dispatch_request()\n",
      "  File \"C:\\Users\\BILHA\\Anaconda3\\lib\\site-packages\\flask\\app.py\", line 1614, in full_dispatch_request\n",
      "    rv = self.handle_user_exception(e)\n",
      "  File \"C:\\Users\\BILHA\\Anaconda3\\lib\\site-packages\\flask\\app.py\", line 1517, in handle_user_exception\n",
      "    reraise(exc_type, exc_value, tb)\n",
      "  File \"C:\\Users\\BILHA\\Anaconda3\\lib\\site-packages\\flask\\_compat.py\", line 33, in reraise\n",
      "    raise value\n",
      "  File \"C:\\Users\\BILHA\\Anaconda3\\lib\\site-packages\\flask\\app.py\", line 1612, in full_dispatch_request\n",
      "    rv = self.dispatch_request()\n",
      "  File \"C:\\Users\\BILHA\\Anaconda3\\lib\\site-packages\\flask\\app.py\", line 1598, in dispatch_request\n",
      "    return self.view_functions[rule.endpoint](**req.view_args)\n",
      "  File \"C:\\Users\\BILHA\\Anaconda3\\lib\\site-packages\\dash\\dash.py\", line 915, in dispatch\n",
      "    return self.callback_map[target_id]['callback'](*args)\n",
      "  File \"C:\\Users\\BILHA\\Anaconda3\\lib\\site-packages\\dash\\dash.py\", line 855, in add_context\n",
      "    output_value = func(*args, **kwargs)\n",
      "  File \"<ipython-input-41-d549e6c83915>\", line 15, in update_output_div\n",
      "    return 'You entered \"{ }\"'.format( input_value)\n",
      "KeyError: ' '\n",
      "127.0.0.1 - - [09/Nov/2018 17:36:05] \"POST /_dash-update-component HTTP/1.1\" 500 -\n",
      "[2018-11-09 17:36:05,326] ERROR in app: Exception on /_dash-update-component [POST]\n",
      "Traceback (most recent call last):\n",
      "  File \"C:\\Users\\BILHA\\Anaconda3\\lib\\site-packages\\flask\\app.py\", line 1982, in wsgi_app\n",
      "    response = self.full_dispatch_request()\n",
      "  File \"C:\\Users\\BILHA\\Anaconda3\\lib\\site-packages\\flask\\app.py\", line 1614, in full_dispatch_request\n",
      "    rv = self.handle_user_exception(e)\n",
      "  File \"C:\\Users\\BILHA\\Anaconda3\\lib\\site-packages\\flask\\app.py\", line 1517, in handle_user_exception\n",
      "    reraise(exc_type, exc_value, tb)\n",
      "  File \"C:\\Users\\BILHA\\Anaconda3\\lib\\site-packages\\flask\\_compat.py\", line 33, in reraise\n",
      "    raise value\n",
      "  File \"C:\\Users\\BILHA\\Anaconda3\\lib\\site-packages\\flask\\app.py\", line 1612, in full_dispatch_request\n",
      "    rv = self.dispatch_request()\n",
      "  File \"C:\\Users\\BILHA\\Anaconda3\\lib\\site-packages\\flask\\app.py\", line 1598, in dispatch_request\n",
      "    return self.view_functions[rule.endpoint](**req.view_args)\n",
      "  File \"C:\\Users\\BILHA\\Anaconda3\\lib\\site-packages\\dash\\dash.py\", line 915, in dispatch\n",
      "    return self.callback_map[target_id]['callback'](*args)\n",
      "  File \"C:\\Users\\BILHA\\Anaconda3\\lib\\site-packages\\dash\\dash.py\", line 855, in add_context\n",
      "    output_value = func(*args, **kwargs)\n",
      "  File \"<ipython-input-41-d549e6c83915>\", line 15, in update_output_div\n",
      "    return 'You entered \"{ }\"'.format( input_value)\n",
      "KeyError: ' '\n",
      "127.0.0.1 - - [09/Nov/2018 17:36:05] \"POST /_dash-update-component HTTP/1.1\" 500 -\n",
      "[2018-11-09 17:36:05,554] ERROR in app: Exception on /_dash-update-component [POST]\n",
      "Traceback (most recent call last):\n",
      "  File \"C:\\Users\\BILHA\\Anaconda3\\lib\\site-packages\\flask\\app.py\", line 1982, in wsgi_app\n",
      "    response = self.full_dispatch_request()\n",
      "  File \"C:\\Users\\BILHA\\Anaconda3\\lib\\site-packages\\flask\\app.py\", line 1614, in full_dispatch_request\n",
      "    rv = self.handle_user_exception(e)\n",
      "  File \"C:\\Users\\BILHA\\Anaconda3\\lib\\site-packages\\flask\\app.py\", line 1517, in handle_user_exception\n",
      "    reraise(exc_type, exc_value, tb)\n",
      "  File \"C:\\Users\\BILHA\\Anaconda3\\lib\\site-packages\\flask\\_compat.py\", line 33, in reraise\n",
      "    raise value\n",
      "  File \"C:\\Users\\BILHA\\Anaconda3\\lib\\site-packages\\flask\\app.py\", line 1612, in full_dispatch_request\n",
      "    rv = self.dispatch_request()\n",
      "  File \"C:\\Users\\BILHA\\Anaconda3\\lib\\site-packages\\flask\\app.py\", line 1598, in dispatch_request\n",
      "    return self.view_functions[rule.endpoint](**req.view_args)\n",
      "  File \"C:\\Users\\BILHA\\Anaconda3\\lib\\site-packages\\dash\\dash.py\", line 915, in dispatch\n",
      "    return self.callback_map[target_id]['callback'](*args)\n",
      "  File \"C:\\Users\\BILHA\\Anaconda3\\lib\\site-packages\\dash\\dash.py\", line 855, in add_context\n",
      "    output_value = func(*args, **kwargs)\n",
      "  File \"<ipython-input-41-d549e6c83915>\", line 15, in update_output_div\n",
      "    return 'You entered \"{ }\"'.format( input_value)\n",
      "KeyError: ' '\n",
      "127.0.0.1 - - [09/Nov/2018 17:36:05] \"POST /_dash-update-component HTTP/1.1\" 500 -\n",
      "[2018-11-09 17:36:07,071] ERROR in app: Exception on /_dash-update-component [POST]\n",
      "Traceback (most recent call last):\n",
      "  File \"C:\\Users\\BILHA\\Anaconda3\\lib\\site-packages\\flask\\app.py\", line 1982, in wsgi_app\n",
      "    response = self.full_dispatch_request()\n",
      "  File \"C:\\Users\\BILHA\\Anaconda3\\lib\\site-packages\\flask\\app.py\", line 1614, in full_dispatch_request\n",
      "    rv = self.handle_user_exception(e)\n",
      "  File \"C:\\Users\\BILHA\\Anaconda3\\lib\\site-packages\\flask\\app.py\", line 1517, in handle_user_exception\n",
      "    reraise(exc_type, exc_value, tb)\n",
      "  File \"C:\\Users\\BILHA\\Anaconda3\\lib\\site-packages\\flask\\_compat.py\", line 33, in reraise\n",
      "    raise value\n",
      "  File \"C:\\Users\\BILHA\\Anaconda3\\lib\\site-packages\\flask\\app.py\", line 1612, in full_dispatch_request\n",
      "    rv = self.dispatch_request()\n",
      "  File \"C:\\Users\\BILHA\\Anaconda3\\lib\\site-packages\\flask\\app.py\", line 1598, in dispatch_request\n",
      "    return self.view_functions[rule.endpoint](**req.view_args)\n",
      "  File \"C:\\Users\\BILHA\\Anaconda3\\lib\\site-packages\\dash\\dash.py\", line 915, in dispatch\n",
      "    return self.callback_map[target_id]['callback'](*args)\n",
      "  File \"C:\\Users\\BILHA\\Anaconda3\\lib\\site-packages\\dash\\dash.py\", line 855, in add_context\n",
      "    output_value = func(*args, **kwargs)\n",
      "  File \"<ipython-input-41-d549e6c83915>\", line 15, in update_output_div\n",
      "    return 'You entered \"{ }\"'.format( input_value)\n",
      "KeyError: ' '\n",
      "127.0.0.1 - - [09/Nov/2018 17:36:07] \"POST /_dash-update-component HTTP/1.1\" 500 -\n",
      "[2018-11-09 17:36:07,292] ERROR in app: Exception on /_dash-update-component [POST]\n",
      "Traceback (most recent call last):\n",
      "  File \"C:\\Users\\BILHA\\Anaconda3\\lib\\site-packages\\flask\\app.py\", line 1982, in wsgi_app\n",
      "    response = self.full_dispatch_request()\n",
      "  File \"C:\\Users\\BILHA\\Anaconda3\\lib\\site-packages\\flask\\app.py\", line 1614, in full_dispatch_request\n",
      "    rv = self.handle_user_exception(e)\n",
      "  File \"C:\\Users\\BILHA\\Anaconda3\\lib\\site-packages\\flask\\app.py\", line 1517, in handle_user_exception\n",
      "    reraise(exc_type, exc_value, tb)\n",
      "  File \"C:\\Users\\BILHA\\Anaconda3\\lib\\site-packages\\flask\\_compat.py\", line 33, in reraise\n",
      "    raise value\n",
      "  File \"C:\\Users\\BILHA\\Anaconda3\\lib\\site-packages\\flask\\app.py\", line 1612, in full_dispatch_request\n",
      "    rv = self.dispatch_request()\n",
      "  File \"C:\\Users\\BILHA\\Anaconda3\\lib\\site-packages\\flask\\app.py\", line 1598, in dispatch_request\n",
      "    return self.view_functions[rule.endpoint](**req.view_args)\n",
      "  File \"C:\\Users\\BILHA\\Anaconda3\\lib\\site-packages\\dash\\dash.py\", line 915, in dispatch\n",
      "    return self.callback_map[target_id]['callback'](*args)\n",
      "  File \"C:\\Users\\BILHA\\Anaconda3\\lib\\site-packages\\dash\\dash.py\", line 855, in add_context\n",
      "    output_value = func(*args, **kwargs)\n",
      "  File \"<ipython-input-41-d549e6c83915>\", line 15, in update_output_div\n",
      "    return 'You entered \"{ }\"'.format( input_value)\n",
      "KeyError: ' '\n",
      "127.0.0.1 - - [09/Nov/2018 17:36:07] \"POST /_dash-update-component HTTP/1.1\" 500 -\n",
      "[2018-11-09 17:36:07,543] ERROR in app: Exception on /_dash-update-component [POST]\n",
      "Traceback (most recent call last):\n",
      "  File \"C:\\Users\\BILHA\\Anaconda3\\lib\\site-packages\\flask\\app.py\", line 1982, in wsgi_app\n",
      "    response = self.full_dispatch_request()\n",
      "  File \"C:\\Users\\BILHA\\Anaconda3\\lib\\site-packages\\flask\\app.py\", line 1614, in full_dispatch_request\n",
      "    rv = self.handle_user_exception(e)\n",
      "  File \"C:\\Users\\BILHA\\Anaconda3\\lib\\site-packages\\flask\\app.py\", line 1517, in handle_user_exception\n",
      "    reraise(exc_type, exc_value, tb)\n",
      "  File \"C:\\Users\\BILHA\\Anaconda3\\lib\\site-packages\\flask\\_compat.py\", line 33, in reraise\n",
      "    raise value\n",
      "  File \"C:\\Users\\BILHA\\Anaconda3\\lib\\site-packages\\flask\\app.py\", line 1612, in full_dispatch_request\n",
      "    rv = self.dispatch_request()\n",
      "  File \"C:\\Users\\BILHA\\Anaconda3\\lib\\site-packages\\flask\\app.py\", line 1598, in dispatch_request\n",
      "    return self.view_functions[rule.endpoint](**req.view_args)\n",
      "  File \"C:\\Users\\BILHA\\Anaconda3\\lib\\site-packages\\dash\\dash.py\", line 915, in dispatch\n",
      "    return self.callback_map[target_id]['callback'](*args)\n",
      "  File \"C:\\Users\\BILHA\\Anaconda3\\lib\\site-packages\\dash\\dash.py\", line 855, in add_context\n",
      "    output_value = func(*args, **kwargs)\n",
      "  File \"<ipython-input-41-d549e6c83915>\", line 15, in update_output_div\n",
      "    return 'You entered \"{ }\"'.format( input_value)\n",
      "KeyError: ' '\n"
     ]
    },
    {
     "name": "stderr",
     "output_type": "stream",
     "text": [
      "127.0.0.1 - - [09/Nov/2018 17:36:07] \"POST /_dash-update-component HTTP/1.1\" 500 -\n",
      "[2018-11-09 17:36:07,857] ERROR in app: Exception on /_dash-update-component [POST]\n",
      "Traceback (most recent call last):\n",
      "  File \"C:\\Users\\BILHA\\Anaconda3\\lib\\site-packages\\flask\\app.py\", line 1982, in wsgi_app\n",
      "    response = self.full_dispatch_request()\n",
      "  File \"C:\\Users\\BILHA\\Anaconda3\\lib\\site-packages\\flask\\app.py\", line 1614, in full_dispatch_request\n",
      "    rv = self.handle_user_exception(e)\n",
      "  File \"C:\\Users\\BILHA\\Anaconda3\\lib\\site-packages\\flask\\app.py\", line 1517, in handle_user_exception\n",
      "    reraise(exc_type, exc_value, tb)\n",
      "  File \"C:\\Users\\BILHA\\Anaconda3\\lib\\site-packages\\flask\\_compat.py\", line 33, in reraise\n",
      "    raise value\n",
      "  File \"C:\\Users\\BILHA\\Anaconda3\\lib\\site-packages\\flask\\app.py\", line 1612, in full_dispatch_request\n",
      "    rv = self.dispatch_request()\n",
      "  File \"C:\\Users\\BILHA\\Anaconda3\\lib\\site-packages\\flask\\app.py\", line 1598, in dispatch_request\n",
      "    return self.view_functions[rule.endpoint](**req.view_args)\n",
      "  File \"C:\\Users\\BILHA\\Anaconda3\\lib\\site-packages\\dash\\dash.py\", line 915, in dispatch\n",
      "    return self.callback_map[target_id]['callback'](*args)\n",
      "  File \"C:\\Users\\BILHA\\Anaconda3\\lib\\site-packages\\dash\\dash.py\", line 855, in add_context\n",
      "    output_value = func(*args, **kwargs)\n",
      "  File \"<ipython-input-41-d549e6c83915>\", line 15, in update_output_div\n",
      "    return 'You entered \"{ }\"'.format( input_value)\n",
      "KeyError: ' '\n",
      "127.0.0.1 - - [09/Nov/2018 17:36:07] \"POST /_dash-update-component HTTP/1.1\" 500 -\n",
      "[2018-11-09 17:36:07,967] ERROR in app: Exception on /_dash-update-component [POST]\n",
      "Traceback (most recent call last):\n",
      "  File \"C:\\Users\\BILHA\\Anaconda3\\lib\\site-packages\\flask\\app.py\", line 1982, in wsgi_app\n",
      "    response = self.full_dispatch_request()\n",
      "  File \"C:\\Users\\BILHA\\Anaconda3\\lib\\site-packages\\flask\\app.py\", line 1614, in full_dispatch_request\n",
      "    rv = self.handle_user_exception(e)\n",
      "  File \"C:\\Users\\BILHA\\Anaconda3\\lib\\site-packages\\flask\\app.py\", line 1517, in handle_user_exception\n",
      "    reraise(exc_type, exc_value, tb)\n",
      "  File \"C:\\Users\\BILHA\\Anaconda3\\lib\\site-packages\\flask\\_compat.py\", line 33, in reraise\n",
      "    raise value\n",
      "  File \"C:\\Users\\BILHA\\Anaconda3\\lib\\site-packages\\flask\\app.py\", line 1612, in full_dispatch_request\n",
      "    rv = self.dispatch_request()\n",
      "  File \"C:\\Users\\BILHA\\Anaconda3\\lib\\site-packages\\flask\\app.py\", line 1598, in dispatch_request\n",
      "    return self.view_functions[rule.endpoint](**req.view_args)\n",
      "  File \"C:\\Users\\BILHA\\Anaconda3\\lib\\site-packages\\dash\\dash.py\", line 915, in dispatch\n",
      "    return self.callback_map[target_id]['callback'](*args)\n",
      "  File \"C:\\Users\\BILHA\\Anaconda3\\lib\\site-packages\\dash\\dash.py\", line 855, in add_context\n",
      "    output_value = func(*args, **kwargs)\n",
      "  File \"<ipython-input-41-d549e6c83915>\", line 15, in update_output_div\n",
      "    return 'You entered \"{ }\"'.format( input_value)\n",
      "KeyError: ' '\n",
      "127.0.0.1 - - [09/Nov/2018 17:36:07] \"POST /_dash-update-component HTTP/1.1\" 500 -\n",
      "[2018-11-09 17:36:08,476] ERROR in app: Exception on /_dash-update-component [POST]\n",
      "Traceback (most recent call last):\n",
      "  File \"C:\\Users\\BILHA\\Anaconda3\\lib\\site-packages\\flask\\app.py\", line 1982, in wsgi_app\n",
      "    response = self.full_dispatch_request()\n",
      "  File \"C:\\Users\\BILHA\\Anaconda3\\lib\\site-packages\\flask\\app.py\", line 1614, in full_dispatch_request\n",
      "    rv = self.handle_user_exception(e)\n",
      "  File \"C:\\Users\\BILHA\\Anaconda3\\lib\\site-packages\\flask\\app.py\", line 1517, in handle_user_exception\n",
      "    reraise(exc_type, exc_value, tb)\n",
      "  File \"C:\\Users\\BILHA\\Anaconda3\\lib\\site-packages\\flask\\_compat.py\", line 33, in reraise\n",
      "    raise value\n",
      "  File \"C:\\Users\\BILHA\\Anaconda3\\lib\\site-packages\\flask\\app.py\", line 1612, in full_dispatch_request\n",
      "    rv = self.dispatch_request()\n",
      "  File \"C:\\Users\\BILHA\\Anaconda3\\lib\\site-packages\\flask\\app.py\", line 1598, in dispatch_request\n",
      "    return self.view_functions[rule.endpoint](**req.view_args)\n",
      "  File \"C:\\Users\\BILHA\\Anaconda3\\lib\\site-packages\\dash\\dash.py\", line 915, in dispatch\n",
      "    return self.callback_map[target_id]['callback'](*args)\n",
      "  File \"C:\\Users\\BILHA\\Anaconda3\\lib\\site-packages\\dash\\dash.py\", line 855, in add_context\n",
      "    output_value = func(*args, **kwargs)\n",
      "  File \"<ipython-input-41-d549e6c83915>\", line 15, in update_output_div\n",
      "    return 'You entered \"{ }\"'.format( input_value)\n",
      "KeyError: ' '\n",
      "127.0.0.1 - - [09/Nov/2018 17:36:08] \"POST /_dash-update-component HTTP/1.1\" 500 -\n",
      "[2018-11-09 17:36:08,750] ERROR in app: Exception on /_dash-update-component [POST]\n",
      "Traceback (most recent call last):\n",
      "  File \"C:\\Users\\BILHA\\Anaconda3\\lib\\site-packages\\flask\\app.py\", line 1982, in wsgi_app\n",
      "    response = self.full_dispatch_request()\n",
      "  File \"C:\\Users\\BILHA\\Anaconda3\\lib\\site-packages\\flask\\app.py\", line 1614, in full_dispatch_request\n",
      "    rv = self.handle_user_exception(e)\n",
      "  File \"C:\\Users\\BILHA\\Anaconda3\\lib\\site-packages\\flask\\app.py\", line 1517, in handle_user_exception\n",
      "    reraise(exc_type, exc_value, tb)\n",
      "  File \"C:\\Users\\BILHA\\Anaconda3\\lib\\site-packages\\flask\\_compat.py\", line 33, in reraise\n",
      "    raise value\n",
      "  File \"C:\\Users\\BILHA\\Anaconda3\\lib\\site-packages\\flask\\app.py\", line 1612, in full_dispatch_request\n",
      "    rv = self.dispatch_request()\n",
      "  File \"C:\\Users\\BILHA\\Anaconda3\\lib\\site-packages\\flask\\app.py\", line 1598, in dispatch_request\n",
      "    return self.view_functions[rule.endpoint](**req.view_args)\n",
      "  File \"C:\\Users\\BILHA\\Anaconda3\\lib\\site-packages\\dash\\dash.py\", line 915, in dispatch\n",
      "    return self.callback_map[target_id]['callback'](*args)\n",
      "  File \"C:\\Users\\BILHA\\Anaconda3\\lib\\site-packages\\dash\\dash.py\", line 855, in add_context\n",
      "    output_value = func(*args, **kwargs)\n",
      "  File \"<ipython-input-41-d549e6c83915>\", line 15, in update_output_div\n",
      "    return 'You entered \"{ }\"'.format( input_value)\n",
      "KeyError: ' '\n",
      "127.0.0.1 - - [09/Nov/2018 17:36:08] \"POST /_dash-update-component HTTP/1.1\" 500 -\n",
      "[2018-11-09 17:36:08,976] ERROR in app: Exception on /_dash-update-component [POST]\n",
      "Traceback (most recent call last):\n",
      "  File \"C:\\Users\\BILHA\\Anaconda3\\lib\\site-packages\\flask\\app.py\", line 1982, in wsgi_app\n",
      "    response = self.full_dispatch_request()\n",
      "  File \"C:\\Users\\BILHA\\Anaconda3\\lib\\site-packages\\flask\\app.py\", line 1614, in full_dispatch_request\n",
      "    rv = self.handle_user_exception(e)\n",
      "  File \"C:\\Users\\BILHA\\Anaconda3\\lib\\site-packages\\flask\\app.py\", line 1517, in handle_user_exception\n",
      "    reraise(exc_type, exc_value, tb)\n",
      "  File \"C:\\Users\\BILHA\\Anaconda3\\lib\\site-packages\\flask\\_compat.py\", line 33, in reraise\n",
      "    raise value\n",
      "  File \"C:\\Users\\BILHA\\Anaconda3\\lib\\site-packages\\flask\\app.py\", line 1612, in full_dispatch_request\n",
      "    rv = self.dispatch_request()\n",
      "  File \"C:\\Users\\BILHA\\Anaconda3\\lib\\site-packages\\flask\\app.py\", line 1598, in dispatch_request\n",
      "    return self.view_functions[rule.endpoint](**req.view_args)\n",
      "  File \"C:\\Users\\BILHA\\Anaconda3\\lib\\site-packages\\dash\\dash.py\", line 915, in dispatch\n",
      "    return self.callback_map[target_id]['callback'](*args)\n",
      "  File \"C:\\Users\\BILHA\\Anaconda3\\lib\\site-packages\\dash\\dash.py\", line 855, in add_context\n",
      "    output_value = func(*args, **kwargs)\n",
      "  File \"<ipython-input-41-d549e6c83915>\", line 15, in update_output_div\n",
      "    return 'You entered \"{ }\"'.format( input_value)\n",
      "KeyError: ' '\n",
      "127.0.0.1 - - [09/Nov/2018 17:36:08] \"POST /_dash-update-component HTTP/1.1\" 500 -\n",
      "[2018-11-09 17:36:09,081] ERROR in app: Exception on /_dash-update-component [POST]\n",
      "Traceback (most recent call last):\n",
      "  File \"C:\\Users\\BILHA\\Anaconda3\\lib\\site-packages\\flask\\app.py\", line 1982, in wsgi_app\n",
      "    response = self.full_dispatch_request()\n",
      "  File \"C:\\Users\\BILHA\\Anaconda3\\lib\\site-packages\\flask\\app.py\", line 1614, in full_dispatch_request\n",
      "    rv = self.handle_user_exception(e)\n",
      "  File \"C:\\Users\\BILHA\\Anaconda3\\lib\\site-packages\\flask\\app.py\", line 1517, in handle_user_exception\n",
      "    reraise(exc_type, exc_value, tb)\n",
      "  File \"C:\\Users\\BILHA\\Anaconda3\\lib\\site-packages\\flask\\_compat.py\", line 33, in reraise\n",
      "    raise value\n",
      "  File \"C:\\Users\\BILHA\\Anaconda3\\lib\\site-packages\\flask\\app.py\", line 1612, in full_dispatch_request\n",
      "    rv = self.dispatch_request()\n",
      "  File \"C:\\Users\\BILHA\\Anaconda3\\lib\\site-packages\\flask\\app.py\", line 1598, in dispatch_request\n",
      "    return self.view_functions[rule.endpoint](**req.view_args)\n",
      "  File \"C:\\Users\\BILHA\\Anaconda3\\lib\\site-packages\\dash\\dash.py\", line 915, in dispatch\n",
      "    return self.callback_map[target_id]['callback'](*args)\n",
      "  File \"C:\\Users\\BILHA\\Anaconda3\\lib\\site-packages\\dash\\dash.py\", line 855, in add_context\n",
      "    output_value = func(*args, **kwargs)\n",
      "  File \"<ipython-input-41-d549e6c83915>\", line 15, in update_output_div\n",
      "    return 'You entered \"{ }\"'.format( input_value)\n",
      "KeyError: ' '\n"
     ]
    },
    {
     "name": "stderr",
     "output_type": "stream",
     "text": [
      "127.0.0.1 - - [09/Nov/2018 17:36:09] \"POST /_dash-update-component HTTP/1.1\" 500 -\n",
      "[2018-11-09 17:36:09,246] ERROR in app: Exception on /_dash-update-component [POST]\n",
      "Traceback (most recent call last):\n",
      "  File \"C:\\Users\\BILHA\\Anaconda3\\lib\\site-packages\\flask\\app.py\", line 1982, in wsgi_app\n",
      "    response = self.full_dispatch_request()\n",
      "  File \"C:\\Users\\BILHA\\Anaconda3\\lib\\site-packages\\flask\\app.py\", line 1614, in full_dispatch_request\n",
      "    rv = self.handle_user_exception(e)\n",
      "  File \"C:\\Users\\BILHA\\Anaconda3\\lib\\site-packages\\flask\\app.py\", line 1517, in handle_user_exception\n",
      "    reraise(exc_type, exc_value, tb)\n",
      "  File \"C:\\Users\\BILHA\\Anaconda3\\lib\\site-packages\\flask\\_compat.py\", line 33, in reraise\n",
      "    raise value\n",
      "  File \"C:\\Users\\BILHA\\Anaconda3\\lib\\site-packages\\flask\\app.py\", line 1612, in full_dispatch_request\n",
      "    rv = self.dispatch_request()\n",
      "  File \"C:\\Users\\BILHA\\Anaconda3\\lib\\site-packages\\flask\\app.py\", line 1598, in dispatch_request\n",
      "    return self.view_functions[rule.endpoint](**req.view_args)\n",
      "  File \"C:\\Users\\BILHA\\Anaconda3\\lib\\site-packages\\dash\\dash.py\", line 915, in dispatch\n",
      "    return self.callback_map[target_id]['callback'](*args)\n",
      "  File \"C:\\Users\\BILHA\\Anaconda3\\lib\\site-packages\\dash\\dash.py\", line 855, in add_context\n",
      "    output_value = func(*args, **kwargs)\n",
      "  File \"<ipython-input-41-d549e6c83915>\", line 15, in update_output_div\n",
      "    return 'You entered \"{ }\"'.format( input_value)\n",
      "KeyError: ' '\n",
      "127.0.0.1 - - [09/Nov/2018 17:36:09] \"POST /_dash-update-component HTTP/1.1\" 500 -\n",
      "[2018-11-09 17:36:09,368] ERROR in app: Exception on /_dash-update-component [POST]\n",
      "Traceback (most recent call last):\n",
      "  File \"C:\\Users\\BILHA\\Anaconda3\\lib\\site-packages\\flask\\app.py\", line 1982, in wsgi_app\n",
      "    response = self.full_dispatch_request()\n",
      "  File \"C:\\Users\\BILHA\\Anaconda3\\lib\\site-packages\\flask\\app.py\", line 1614, in full_dispatch_request\n",
      "    rv = self.handle_user_exception(e)\n",
      "  File \"C:\\Users\\BILHA\\Anaconda3\\lib\\site-packages\\flask\\app.py\", line 1517, in handle_user_exception\n",
      "    reraise(exc_type, exc_value, tb)\n",
      "  File \"C:\\Users\\BILHA\\Anaconda3\\lib\\site-packages\\flask\\_compat.py\", line 33, in reraise\n",
      "    raise value\n",
      "  File \"C:\\Users\\BILHA\\Anaconda3\\lib\\site-packages\\flask\\app.py\", line 1612, in full_dispatch_request\n",
      "    rv = self.dispatch_request()\n",
      "  File \"C:\\Users\\BILHA\\Anaconda3\\lib\\site-packages\\flask\\app.py\", line 1598, in dispatch_request\n",
      "    return self.view_functions[rule.endpoint](**req.view_args)\n",
      "  File \"C:\\Users\\BILHA\\Anaconda3\\lib\\site-packages\\dash\\dash.py\", line 915, in dispatch\n",
      "    return self.callback_map[target_id]['callback'](*args)\n",
      "  File \"C:\\Users\\BILHA\\Anaconda3\\lib\\site-packages\\dash\\dash.py\", line 855, in add_context\n",
      "    output_value = func(*args, **kwargs)\n",
      "  File \"<ipython-input-41-d549e6c83915>\", line 15, in update_output_div\n",
      "    return 'You entered \"{ }\"'.format( input_value)\n",
      "KeyError: ' '\n",
      "127.0.0.1 - - [09/Nov/2018 17:36:09] \"POST /_dash-update-component HTTP/1.1\" 500 -\n",
      "[2018-11-09 17:36:09,539] ERROR in app: Exception on /_dash-update-component [POST]\n",
      "Traceback (most recent call last):\n",
      "  File \"C:\\Users\\BILHA\\Anaconda3\\lib\\site-packages\\flask\\app.py\", line 1982, in wsgi_app\n",
      "    response = self.full_dispatch_request()\n",
      "  File \"C:\\Users\\BILHA\\Anaconda3\\lib\\site-packages\\flask\\app.py\", line 1614, in full_dispatch_request\n",
      "    rv = self.handle_user_exception(e)\n",
      "  File \"C:\\Users\\BILHA\\Anaconda3\\lib\\site-packages\\flask\\app.py\", line 1517, in handle_user_exception\n",
      "    reraise(exc_type, exc_value, tb)\n",
      "  File \"C:\\Users\\BILHA\\Anaconda3\\lib\\site-packages\\flask\\_compat.py\", line 33, in reraise\n",
      "    raise value\n",
      "  File \"C:\\Users\\BILHA\\Anaconda3\\lib\\site-packages\\flask\\app.py\", line 1612, in full_dispatch_request\n",
      "    rv = self.dispatch_request()\n",
      "  File \"C:\\Users\\BILHA\\Anaconda3\\lib\\site-packages\\flask\\app.py\", line 1598, in dispatch_request\n",
      "    return self.view_functions[rule.endpoint](**req.view_args)\n",
      "  File \"C:\\Users\\BILHA\\Anaconda3\\lib\\site-packages\\dash\\dash.py\", line 915, in dispatch\n",
      "    return self.callback_map[target_id]['callback'](*args)\n",
      "  File \"C:\\Users\\BILHA\\Anaconda3\\lib\\site-packages\\dash\\dash.py\", line 855, in add_context\n",
      "    output_value = func(*args, **kwargs)\n",
      "  File \"<ipython-input-41-d549e6c83915>\", line 15, in update_output_div\n",
      "    return 'You entered \"{ }\"'.format( input_value)\n",
      "KeyError: ' '\n",
      "127.0.0.1 - - [09/Nov/2018 17:36:09] \"POST /_dash-update-component HTTP/1.1\" 500 -\n",
      "[2018-11-09 17:36:09,645] ERROR in app: Exception on /_dash-update-component [POST]\n",
      "Traceback (most recent call last):\n",
      "  File \"C:\\Users\\BILHA\\Anaconda3\\lib\\site-packages\\flask\\app.py\", line 1982, in wsgi_app\n",
      "    response = self.full_dispatch_request()\n",
      "  File \"C:\\Users\\BILHA\\Anaconda3\\lib\\site-packages\\flask\\app.py\", line 1614, in full_dispatch_request\n",
      "    rv = self.handle_user_exception(e)\n",
      "  File \"C:\\Users\\BILHA\\Anaconda3\\lib\\site-packages\\flask\\app.py\", line 1517, in handle_user_exception\n",
      "    reraise(exc_type, exc_value, tb)\n",
      "  File \"C:\\Users\\BILHA\\Anaconda3\\lib\\site-packages\\flask\\_compat.py\", line 33, in reraise\n",
      "    raise value\n",
      "  File \"C:\\Users\\BILHA\\Anaconda3\\lib\\site-packages\\flask\\app.py\", line 1612, in full_dispatch_request\n",
      "    rv = self.dispatch_request()\n",
      "  File \"C:\\Users\\BILHA\\Anaconda3\\lib\\site-packages\\flask\\app.py\", line 1598, in dispatch_request\n",
      "    return self.view_functions[rule.endpoint](**req.view_args)\n",
      "  File \"C:\\Users\\BILHA\\Anaconda3\\lib\\site-packages\\dash\\dash.py\", line 915, in dispatch\n",
      "    return self.callback_map[target_id]['callback'](*args)\n",
      "  File \"C:\\Users\\BILHA\\Anaconda3\\lib\\site-packages\\dash\\dash.py\", line 855, in add_context\n",
      "    output_value = func(*args, **kwargs)\n",
      "  File \"<ipython-input-41-d549e6c83915>\", line 15, in update_output_div\n",
      "    return 'You entered \"{ }\"'.format( input_value)\n",
      "KeyError: ' '\n",
      "127.0.0.1 - - [09/Nov/2018 17:36:09] \"POST /_dash-update-component HTTP/1.1\" 500 -\n",
      "[2018-11-09 17:36:10,525] ERROR in app: Exception on /_dash-update-component [POST]\n",
      "Traceback (most recent call last):\n",
      "  File \"C:\\Users\\BILHA\\Anaconda3\\lib\\site-packages\\flask\\app.py\", line 1982, in wsgi_app\n",
      "    response = self.full_dispatch_request()\n",
      "  File \"C:\\Users\\BILHA\\Anaconda3\\lib\\site-packages\\flask\\app.py\", line 1614, in full_dispatch_request\n",
      "    rv = self.handle_user_exception(e)\n",
      "  File \"C:\\Users\\BILHA\\Anaconda3\\lib\\site-packages\\flask\\app.py\", line 1517, in handle_user_exception\n",
      "    reraise(exc_type, exc_value, tb)\n",
      "  File \"C:\\Users\\BILHA\\Anaconda3\\lib\\site-packages\\flask\\_compat.py\", line 33, in reraise\n",
      "    raise value\n",
      "  File \"C:\\Users\\BILHA\\Anaconda3\\lib\\site-packages\\flask\\app.py\", line 1612, in full_dispatch_request\n",
      "    rv = self.dispatch_request()\n",
      "  File \"C:\\Users\\BILHA\\Anaconda3\\lib\\site-packages\\flask\\app.py\", line 1598, in dispatch_request\n",
      "    return self.view_functions[rule.endpoint](**req.view_args)\n",
      "  File \"C:\\Users\\BILHA\\Anaconda3\\lib\\site-packages\\dash\\dash.py\", line 915, in dispatch\n",
      "    return self.callback_map[target_id]['callback'](*args)\n",
      "  File \"C:\\Users\\BILHA\\Anaconda3\\lib\\site-packages\\dash\\dash.py\", line 855, in add_context\n",
      "    output_value = func(*args, **kwargs)\n",
      "  File \"<ipython-input-41-d549e6c83915>\", line 15, in update_output_div\n",
      "    return 'You entered \"{ }\"'.format( input_value)\n",
      "KeyError: ' '\n",
      "127.0.0.1 - - [09/Nov/2018 17:36:10] \"POST /_dash-update-component HTTP/1.1\" 500 -\n",
      "[2018-11-09 17:36:10,710] ERROR in app: Exception on /_dash-update-component [POST]\n",
      "Traceback (most recent call last):\n",
      "  File \"C:\\Users\\BILHA\\Anaconda3\\lib\\site-packages\\flask\\app.py\", line 1982, in wsgi_app\n",
      "    response = self.full_dispatch_request()\n",
      "  File \"C:\\Users\\BILHA\\Anaconda3\\lib\\site-packages\\flask\\app.py\", line 1614, in full_dispatch_request\n",
      "    rv = self.handle_user_exception(e)\n",
      "  File \"C:\\Users\\BILHA\\Anaconda3\\lib\\site-packages\\flask\\app.py\", line 1517, in handle_user_exception\n",
      "    reraise(exc_type, exc_value, tb)\n",
      "  File \"C:\\Users\\BILHA\\Anaconda3\\lib\\site-packages\\flask\\_compat.py\", line 33, in reraise\n",
      "    raise value\n",
      "  File \"C:\\Users\\BILHA\\Anaconda3\\lib\\site-packages\\flask\\app.py\", line 1612, in full_dispatch_request\n",
      "    rv = self.dispatch_request()\n",
      "  File \"C:\\Users\\BILHA\\Anaconda3\\lib\\site-packages\\flask\\app.py\", line 1598, in dispatch_request\n",
      "    return self.view_functions[rule.endpoint](**req.view_args)\n",
      "  File \"C:\\Users\\BILHA\\Anaconda3\\lib\\site-packages\\dash\\dash.py\", line 915, in dispatch\n",
      "    return self.callback_map[target_id]['callback'](*args)\n",
      "  File \"C:\\Users\\BILHA\\Anaconda3\\lib\\site-packages\\dash\\dash.py\", line 855, in add_context\n",
      "    output_value = func(*args, **kwargs)\n",
      "  File \"<ipython-input-41-d549e6c83915>\", line 15, in update_output_div\n",
      "    return 'You entered \"{ }\"'.format( input_value)\n",
      "KeyError: ' '\n"
     ]
    },
    {
     "name": "stderr",
     "output_type": "stream",
     "text": [
      "127.0.0.1 - - [09/Nov/2018 17:36:10] \"POST /_dash-update-component HTTP/1.1\" 500 -\n",
      "[2018-11-09 17:36:10,877] ERROR in app: Exception on /_dash-update-component [POST]\n",
      "Traceback (most recent call last):\n",
      "  File \"C:\\Users\\BILHA\\Anaconda3\\lib\\site-packages\\flask\\app.py\", line 1982, in wsgi_app\n",
      "    response = self.full_dispatch_request()\n",
      "  File \"C:\\Users\\BILHA\\Anaconda3\\lib\\site-packages\\flask\\app.py\", line 1614, in full_dispatch_request\n",
      "    rv = self.handle_user_exception(e)\n",
      "  File \"C:\\Users\\BILHA\\Anaconda3\\lib\\site-packages\\flask\\app.py\", line 1517, in handle_user_exception\n",
      "    reraise(exc_type, exc_value, tb)\n",
      "  File \"C:\\Users\\BILHA\\Anaconda3\\lib\\site-packages\\flask\\_compat.py\", line 33, in reraise\n",
      "    raise value\n",
      "  File \"C:\\Users\\BILHA\\Anaconda3\\lib\\site-packages\\flask\\app.py\", line 1612, in full_dispatch_request\n",
      "    rv = self.dispatch_request()\n",
      "  File \"C:\\Users\\BILHA\\Anaconda3\\lib\\site-packages\\flask\\app.py\", line 1598, in dispatch_request\n",
      "    return self.view_functions[rule.endpoint](**req.view_args)\n",
      "  File \"C:\\Users\\BILHA\\Anaconda3\\lib\\site-packages\\dash\\dash.py\", line 915, in dispatch\n",
      "    return self.callback_map[target_id]['callback'](*args)\n",
      "  File \"C:\\Users\\BILHA\\Anaconda3\\lib\\site-packages\\dash\\dash.py\", line 855, in add_context\n",
      "    output_value = func(*args, **kwargs)\n",
      "  File \"<ipython-input-41-d549e6c83915>\", line 15, in update_output_div\n",
      "    return 'You entered \"{ }\"'.format( input_value)\n",
      "KeyError: ' '\n",
      "127.0.0.1 - - [09/Nov/2018 17:36:10] \"POST /_dash-update-component HTTP/1.1\" 500 -\n",
      "[2018-11-09 17:36:11,063] ERROR in app: Exception on /_dash-update-component [POST]\n",
      "Traceback (most recent call last):\n",
      "  File \"C:\\Users\\BILHA\\Anaconda3\\lib\\site-packages\\flask\\app.py\", line 1982, in wsgi_app\n",
      "    response = self.full_dispatch_request()\n",
      "  File \"C:\\Users\\BILHA\\Anaconda3\\lib\\site-packages\\flask\\app.py\", line 1614, in full_dispatch_request\n",
      "    rv = self.handle_user_exception(e)\n",
      "  File \"C:\\Users\\BILHA\\Anaconda3\\lib\\site-packages\\flask\\app.py\", line 1517, in handle_user_exception\n",
      "    reraise(exc_type, exc_value, tb)\n",
      "  File \"C:\\Users\\BILHA\\Anaconda3\\lib\\site-packages\\flask\\_compat.py\", line 33, in reraise\n",
      "    raise value\n",
      "  File \"C:\\Users\\BILHA\\Anaconda3\\lib\\site-packages\\flask\\app.py\", line 1612, in full_dispatch_request\n",
      "    rv = self.dispatch_request()\n",
      "  File \"C:\\Users\\BILHA\\Anaconda3\\lib\\site-packages\\flask\\app.py\", line 1598, in dispatch_request\n",
      "    return self.view_functions[rule.endpoint](**req.view_args)\n",
      "  File \"C:\\Users\\BILHA\\Anaconda3\\lib\\site-packages\\dash\\dash.py\", line 915, in dispatch\n",
      "    return self.callback_map[target_id]['callback'](*args)\n",
      "  File \"C:\\Users\\BILHA\\Anaconda3\\lib\\site-packages\\dash\\dash.py\", line 855, in add_context\n",
      "    output_value = func(*args, **kwargs)\n",
      "  File \"<ipython-input-41-d549e6c83915>\", line 15, in update_output_div\n",
      "    return 'You entered \"{ }\"'.format( input_value)\n",
      "KeyError: ' '\n",
      "127.0.0.1 - - [09/Nov/2018 17:36:11] \"POST /_dash-update-component HTTP/1.1\" 500 -\n",
      "[2018-11-09 17:36:11,168] ERROR in app: Exception on /_dash-update-component [POST]\n",
      "Traceback (most recent call last):\n",
      "  File \"C:\\Users\\BILHA\\Anaconda3\\lib\\site-packages\\flask\\app.py\", line 1982, in wsgi_app\n",
      "    response = self.full_dispatch_request()\n",
      "  File \"C:\\Users\\BILHA\\Anaconda3\\lib\\site-packages\\flask\\app.py\", line 1614, in full_dispatch_request\n",
      "    rv = self.handle_user_exception(e)\n",
      "  File \"C:\\Users\\BILHA\\Anaconda3\\lib\\site-packages\\flask\\app.py\", line 1517, in handle_user_exception\n",
      "    reraise(exc_type, exc_value, tb)\n",
      "  File \"C:\\Users\\BILHA\\Anaconda3\\lib\\site-packages\\flask\\_compat.py\", line 33, in reraise\n",
      "    raise value\n",
      "  File \"C:\\Users\\BILHA\\Anaconda3\\lib\\site-packages\\flask\\app.py\", line 1612, in full_dispatch_request\n",
      "    rv = self.dispatch_request()\n",
      "  File \"C:\\Users\\BILHA\\Anaconda3\\lib\\site-packages\\flask\\app.py\", line 1598, in dispatch_request\n",
      "    return self.view_functions[rule.endpoint](**req.view_args)\n",
      "  File \"C:\\Users\\BILHA\\Anaconda3\\lib\\site-packages\\dash\\dash.py\", line 915, in dispatch\n",
      "    return self.callback_map[target_id]['callback'](*args)\n",
      "  File \"C:\\Users\\BILHA\\Anaconda3\\lib\\site-packages\\dash\\dash.py\", line 855, in add_context\n",
      "    output_value = func(*args, **kwargs)\n",
      "  File \"<ipython-input-41-d549e6c83915>\", line 15, in update_output_div\n",
      "    return 'You entered \"{ }\"'.format( input_value)\n",
      "KeyError: ' '\n",
      "127.0.0.1 - - [09/Nov/2018 17:36:11] \"POST /_dash-update-component HTTP/1.1\" 500 -\n",
      "[2018-11-09 17:36:11,373] ERROR in app: Exception on /_dash-update-component [POST]\n",
      "Traceback (most recent call last):\n",
      "  File \"C:\\Users\\BILHA\\Anaconda3\\lib\\site-packages\\flask\\app.py\", line 1982, in wsgi_app\n",
      "    response = self.full_dispatch_request()\n",
      "  File \"C:\\Users\\BILHA\\Anaconda3\\lib\\site-packages\\flask\\app.py\", line 1614, in full_dispatch_request\n",
      "    rv = self.handle_user_exception(e)\n",
      "  File \"C:\\Users\\BILHA\\Anaconda3\\lib\\site-packages\\flask\\app.py\", line 1517, in handle_user_exception\n",
      "    reraise(exc_type, exc_value, tb)\n",
      "  File \"C:\\Users\\BILHA\\Anaconda3\\lib\\site-packages\\flask\\_compat.py\", line 33, in reraise\n",
      "    raise value\n",
      "  File \"C:\\Users\\BILHA\\Anaconda3\\lib\\site-packages\\flask\\app.py\", line 1612, in full_dispatch_request\n",
      "    rv = self.dispatch_request()\n",
      "  File \"C:\\Users\\BILHA\\Anaconda3\\lib\\site-packages\\flask\\app.py\", line 1598, in dispatch_request\n",
      "    return self.view_functions[rule.endpoint](**req.view_args)\n",
      "  File \"C:\\Users\\BILHA\\Anaconda3\\lib\\site-packages\\dash\\dash.py\", line 915, in dispatch\n",
      "    return self.callback_map[target_id]['callback'](*args)\n",
      "  File \"C:\\Users\\BILHA\\Anaconda3\\lib\\site-packages\\dash\\dash.py\", line 855, in add_context\n",
      "    output_value = func(*args, **kwargs)\n",
      "  File \"<ipython-input-41-d549e6c83915>\", line 15, in update_output_div\n",
      "    return 'You entered \"{ }\"'.format( input_value)\n",
      "KeyError: ' '\n",
      "127.0.0.1 - - [09/Nov/2018 17:36:11] \"POST /_dash-update-component HTTP/1.1\" 500 -\n",
      "[2018-11-09 17:36:11,723] ERROR in app: Exception on /_dash-update-component [POST]\n",
      "Traceback (most recent call last):\n",
      "  File \"C:\\Users\\BILHA\\Anaconda3\\lib\\site-packages\\flask\\app.py\", line 1982, in wsgi_app\n",
      "    response = self.full_dispatch_request()\n",
      "  File \"C:\\Users\\BILHA\\Anaconda3\\lib\\site-packages\\flask\\app.py\", line 1614, in full_dispatch_request\n",
      "    rv = self.handle_user_exception(e)\n",
      "  File \"C:\\Users\\BILHA\\Anaconda3\\lib\\site-packages\\flask\\app.py\", line 1517, in handle_user_exception\n",
      "    reraise(exc_type, exc_value, tb)\n",
      "  File \"C:\\Users\\BILHA\\Anaconda3\\lib\\site-packages\\flask\\_compat.py\", line 33, in reraise\n",
      "    raise value\n",
      "  File \"C:\\Users\\BILHA\\Anaconda3\\lib\\site-packages\\flask\\app.py\", line 1612, in full_dispatch_request\n",
      "    rv = self.dispatch_request()\n",
      "  File \"C:\\Users\\BILHA\\Anaconda3\\lib\\site-packages\\flask\\app.py\", line 1598, in dispatch_request\n",
      "    return self.view_functions[rule.endpoint](**req.view_args)\n",
      "  File \"C:\\Users\\BILHA\\Anaconda3\\lib\\site-packages\\dash\\dash.py\", line 915, in dispatch\n",
      "    return self.callback_map[target_id]['callback'](*args)\n",
      "  File \"C:\\Users\\BILHA\\Anaconda3\\lib\\site-packages\\dash\\dash.py\", line 855, in add_context\n",
      "    output_value = func(*args, **kwargs)\n",
      "  File \"<ipython-input-41-d549e6c83915>\", line 15, in update_output_div\n",
      "    return 'You entered \"{ }\"'.format( input_value)\n",
      "KeyError: ' '\n",
      "127.0.0.1 - - [09/Nov/2018 17:36:11] \"POST /_dash-update-component HTTP/1.1\" 500 -\n",
      "[2018-11-09 17:36:13,256] ERROR in app: Exception on /_dash-update-component [POST]\n",
      "Traceback (most recent call last):\n",
      "  File \"C:\\Users\\BILHA\\Anaconda3\\lib\\site-packages\\flask\\app.py\", line 1982, in wsgi_app\n",
      "    response = self.full_dispatch_request()\n",
      "  File \"C:\\Users\\BILHA\\Anaconda3\\lib\\site-packages\\flask\\app.py\", line 1614, in full_dispatch_request\n",
      "    rv = self.handle_user_exception(e)\n",
      "  File \"C:\\Users\\BILHA\\Anaconda3\\lib\\site-packages\\flask\\app.py\", line 1517, in handle_user_exception\n",
      "    reraise(exc_type, exc_value, tb)\n",
      "  File \"C:\\Users\\BILHA\\Anaconda3\\lib\\site-packages\\flask\\_compat.py\", line 33, in reraise\n",
      "    raise value\n",
      "  File \"C:\\Users\\BILHA\\Anaconda3\\lib\\site-packages\\flask\\app.py\", line 1612, in full_dispatch_request\n",
      "    rv = self.dispatch_request()\n",
      "  File \"C:\\Users\\BILHA\\Anaconda3\\lib\\site-packages\\flask\\app.py\", line 1598, in dispatch_request\n",
      "    return self.view_functions[rule.endpoint](**req.view_args)\n",
      "  File \"C:\\Users\\BILHA\\Anaconda3\\lib\\site-packages\\dash\\dash.py\", line 915, in dispatch\n",
      "    return self.callback_map[target_id]['callback'](*args)\n",
      "  File \"C:\\Users\\BILHA\\Anaconda3\\lib\\site-packages\\dash\\dash.py\", line 855, in add_context\n",
      "    output_value = func(*args, **kwargs)\n",
      "  File \"<ipython-input-41-d549e6c83915>\", line 15, in update_output_div\n",
      "    return 'You entered \"{ }\"'.format( input_value)\n",
      "KeyError: ' '\n"
     ]
    },
    {
     "name": "stderr",
     "output_type": "stream",
     "text": [
      "127.0.0.1 - - [09/Nov/2018 17:36:13] \"POST /_dash-update-component HTTP/1.1\" 500 -\n",
      "[2018-11-09 17:36:18,689] ERROR in app: Exception on /_dash-update-component [POST]\n",
      "Traceback (most recent call last):\n",
      "  File \"C:\\Users\\BILHA\\Anaconda3\\lib\\site-packages\\flask\\app.py\", line 1982, in wsgi_app\n",
      "    response = self.full_dispatch_request()\n",
      "  File \"C:\\Users\\BILHA\\Anaconda3\\lib\\site-packages\\flask\\app.py\", line 1614, in full_dispatch_request\n",
      "    rv = self.handle_user_exception(e)\n",
      "  File \"C:\\Users\\BILHA\\Anaconda3\\lib\\site-packages\\flask\\app.py\", line 1517, in handle_user_exception\n",
      "    reraise(exc_type, exc_value, tb)\n",
      "  File \"C:\\Users\\BILHA\\Anaconda3\\lib\\site-packages\\flask\\_compat.py\", line 33, in reraise\n",
      "    raise value\n",
      "  File \"C:\\Users\\BILHA\\Anaconda3\\lib\\site-packages\\flask\\app.py\", line 1612, in full_dispatch_request\n",
      "    rv = self.dispatch_request()\n",
      "  File \"C:\\Users\\BILHA\\Anaconda3\\lib\\site-packages\\flask\\app.py\", line 1598, in dispatch_request\n",
      "    return self.view_functions[rule.endpoint](**req.view_args)\n",
      "  File \"C:\\Users\\BILHA\\Anaconda3\\lib\\site-packages\\dash\\dash.py\", line 915, in dispatch\n",
      "    return self.callback_map[target_id]['callback'](*args)\n",
      "  File \"C:\\Users\\BILHA\\Anaconda3\\lib\\site-packages\\dash\\dash.py\", line 855, in add_context\n",
      "    output_value = func(*args, **kwargs)\n",
      "  File \"<ipython-input-41-d549e6c83915>\", line 15, in update_output_div\n",
      "    return 'You entered \"{ }\"'.format( input_value)\n",
      "KeyError: ' '\n",
      "127.0.0.1 - - [09/Nov/2018 17:36:18] \"POST /_dash-update-component HTTP/1.1\" 500 -\n"
     ]
    }
   ],
   "source": [
    "### Now with Call backs\n",
    "\n",
    "app = dash.Dash( __name__, external_stylesheets=external_stylesheets)\n",
    "\n",
    "app.layout = dhtml.Div([\n",
    "    dcc.Input( id='tl1', type='text', value='enter category'),\n",
    "    dhtml.Div( id = 'td1', children='Hellow World!!!' )\n",
    "])\n",
    "\n",
    "@app.callback(\n",
    "    Output( component_id='td1', component_property='children'), \n",
    "    [Input( component_id='tl1', component_property='value')]\n",
    ")\n",
    "def update_output_div( input_value):\n",
    "    return 'You entered \"{ }\"'.format( input_value)\n",
    "\n",
    "\n",
    "app.run_server()"
   ]
  },
  {
   "cell_type": "code",
   "execution_count": null,
   "metadata": {
    "scrolled": false
   },
   "outputs": [
    {
     "data": {
      "text/html": [
       "<a href=\"http://localhost:9999\" target=\"_new\">Open in new window</a><hr><iframe src=\"http://localhost:9999\" width=700 height=350></iframe>"
      ]
     },
     "metadata": {},
     "output_type": "display_data"
    },
    {
     "name": "stderr",
     "output_type": "stream",
     "text": [
      " * Running on http://0.0.0.0:9999/ (Press CTRL+C to quit)\n",
      "127.0.0.1 - - [09/Nov/2018 17:44:01] \"GET / HTTP/1.1\" 200 -\n",
      "127.0.0.1 - - [09/Nov/2018 17:44:02] \"GET /_dash-layout HTTP/1.1\" 200 -\n",
      "127.0.0.1 - - [09/Nov/2018 17:44:02] \"GET /_dash-dependencies HTTP/1.1\" 200 -\n",
      "[2018-11-09 17:44:02,480] ERROR in app: Exception on /_dash-update-component [POST]\n",
      "Traceback (most recent call last):\n",
      "  File \"C:\\Users\\BILHA\\Anaconda3\\lib\\site-packages\\flask\\app.py\", line 1982, in wsgi_app\n",
      "    response = self.full_dispatch_request()\n",
      "  File \"C:\\Users\\BILHA\\Anaconda3\\lib\\site-packages\\flask\\app.py\", line 1614, in full_dispatch_request\n",
      "    rv = self.handle_user_exception(e)\n",
      "  File \"C:\\Users\\BILHA\\Anaconda3\\lib\\site-packages\\flask\\app.py\", line 1517, in handle_user_exception\n",
      "    reraise(exc_type, exc_value, tb)\n",
      "  File \"C:\\Users\\BILHA\\Anaconda3\\lib\\site-packages\\flask\\_compat.py\", line 33, in reraise\n",
      "    raise value\n",
      "  File \"C:\\Users\\BILHA\\Anaconda3\\lib\\site-packages\\flask\\app.py\", line 1612, in full_dispatch_request\n",
      "    rv = self.dispatch_request()\n",
      "  File \"C:\\Users\\BILHA\\Anaconda3\\lib\\site-packages\\flask\\app.py\", line 1598, in dispatch_request\n",
      "    return self.view_functions[rule.endpoint](**req.view_args)\n",
      "  File \"C:\\Users\\BILHA\\Anaconda3\\lib\\site-packages\\dash\\dash.py\", line 915, in dispatch\n",
      "    return self.callback_map[target_id]['callback'](*args)\n",
      "  File \"C:\\Users\\BILHA\\Anaconda3\\lib\\site-packages\\dash\\dash.py\", line 855, in add_context\n",
      "    output_value = func(*args, **kwargs)\n",
      "  File \"<ipython-input-41-d549e6c83915>\", line 15, in update_output_div\n",
      "    return 'You entered \"{ }\"'.format( input_value)\n",
      "KeyError: ' '\n",
      "127.0.0.1 - - [09/Nov/2018 17:44:02] \"POST /_dash-update-component HTTP/1.1\" 500 -\n",
      "[2018-11-09 17:44:06,817] ERROR in app: Exception on /_dash-update-component [POST]\n",
      "Traceback (most recent call last):\n",
      "  File \"C:\\Users\\BILHA\\Anaconda3\\lib\\site-packages\\flask\\app.py\", line 1982, in wsgi_app\n",
      "    response = self.full_dispatch_request()\n",
      "  File \"C:\\Users\\BILHA\\Anaconda3\\lib\\site-packages\\flask\\app.py\", line 1614, in full_dispatch_request\n",
      "    rv = self.handle_user_exception(e)\n",
      "  File \"C:\\Users\\BILHA\\Anaconda3\\lib\\site-packages\\flask\\app.py\", line 1517, in handle_user_exception\n",
      "    reraise(exc_type, exc_value, tb)\n",
      "  File \"C:\\Users\\BILHA\\Anaconda3\\lib\\site-packages\\flask\\_compat.py\", line 33, in reraise\n",
      "    raise value\n",
      "  File \"C:\\Users\\BILHA\\Anaconda3\\lib\\site-packages\\flask\\app.py\", line 1612, in full_dispatch_request\n",
      "    rv = self.dispatch_request()\n",
      "  File \"C:\\Users\\BILHA\\Anaconda3\\lib\\site-packages\\flask\\app.py\", line 1598, in dispatch_request\n",
      "    return self.view_functions[rule.endpoint](**req.view_args)\n",
      "  File \"C:\\Users\\BILHA\\Anaconda3\\lib\\site-packages\\dash\\dash.py\", line 915, in dispatch\n",
      "    return self.callback_map[target_id]['callback'](*args)\n",
      "  File \"C:\\Users\\BILHA\\Anaconda3\\lib\\site-packages\\dash\\dash.py\", line 855, in add_context\n",
      "    output_value = func(*args, **kwargs)\n",
      "  File \"<ipython-input-41-d549e6c83915>\", line 15, in update_output_div\n",
      "    return 'You entered \"{ }\"'.format( input_value)\n",
      "KeyError: ' '\n",
      "127.0.0.1 - - [09/Nov/2018 17:44:06] \"POST /_dash-update-component HTTP/1.1\" 500 -\n",
      "[2018-11-09 17:44:06,981] ERROR in app: Exception on /_dash-update-component [POST]\n",
      "Traceback (most recent call last):\n",
      "  File \"C:\\Users\\BILHA\\Anaconda3\\lib\\site-packages\\flask\\app.py\", line 1982, in wsgi_app\n",
      "    response = self.full_dispatch_request()\n",
      "  File \"C:\\Users\\BILHA\\Anaconda3\\lib\\site-packages\\flask\\app.py\", line 1614, in full_dispatch_request\n",
      "    rv = self.handle_user_exception(e)\n",
      "  File \"C:\\Users\\BILHA\\Anaconda3\\lib\\site-packages\\flask\\app.py\", line 1517, in handle_user_exception\n",
      "    reraise(exc_type, exc_value, tb)\n",
      "  File \"C:\\Users\\BILHA\\Anaconda3\\lib\\site-packages\\flask\\_compat.py\", line 33, in reraise\n",
      "    raise value\n",
      "  File \"C:\\Users\\BILHA\\Anaconda3\\lib\\site-packages\\flask\\app.py\", line 1612, in full_dispatch_request\n",
      "    rv = self.dispatch_request()\n",
      "  File \"C:\\Users\\BILHA\\Anaconda3\\lib\\site-packages\\flask\\app.py\", line 1598, in dispatch_request\n",
      "    return self.view_functions[rule.endpoint](**req.view_args)\n",
      "  File \"C:\\Users\\BILHA\\Anaconda3\\lib\\site-packages\\dash\\dash.py\", line 915, in dispatch\n",
      "    return self.callback_map[target_id]['callback'](*args)\n",
      "  File \"C:\\Users\\BILHA\\Anaconda3\\lib\\site-packages\\dash\\dash.py\", line 855, in add_context\n",
      "    output_value = func(*args, **kwargs)\n",
      "  File \"<ipython-input-41-d549e6c83915>\", line 15, in update_output_div\n",
      "    return 'You entered \"{ }\"'.format( input_value)\n",
      "KeyError: ' '\n",
      "127.0.0.1 - - [09/Nov/2018 17:44:06] \"POST /_dash-update-component HTTP/1.1\" 500 -\n",
      "[2018-11-09 17:44:07,151] ERROR in app: Exception on /_dash-update-component [POST]\n",
      "Traceback (most recent call last):\n",
      "  File \"C:\\Users\\BILHA\\Anaconda3\\lib\\site-packages\\flask\\app.py\", line 1982, in wsgi_app\n",
      "    response = self.full_dispatch_request()\n",
      "  File \"C:\\Users\\BILHA\\Anaconda3\\lib\\site-packages\\flask\\app.py\", line 1614, in full_dispatch_request\n",
      "    rv = self.handle_user_exception(e)\n",
      "  File \"C:\\Users\\BILHA\\Anaconda3\\lib\\site-packages\\flask\\app.py\", line 1517, in handle_user_exception\n",
      "    reraise(exc_type, exc_value, tb)\n",
      "  File \"C:\\Users\\BILHA\\Anaconda3\\lib\\site-packages\\flask\\_compat.py\", line 33, in reraise\n",
      "    raise value\n",
      "  File \"C:\\Users\\BILHA\\Anaconda3\\lib\\site-packages\\flask\\app.py\", line 1612, in full_dispatch_request\n",
      "    rv = self.dispatch_request()\n",
      "  File \"C:\\Users\\BILHA\\Anaconda3\\lib\\site-packages\\flask\\app.py\", line 1598, in dispatch_request\n",
      "    return self.view_functions[rule.endpoint](**req.view_args)\n",
      "  File \"C:\\Users\\BILHA\\Anaconda3\\lib\\site-packages\\dash\\dash.py\", line 915, in dispatch\n",
      "    return self.callback_map[target_id]['callback'](*args)\n",
      "  File \"C:\\Users\\BILHA\\Anaconda3\\lib\\site-packages\\dash\\dash.py\", line 855, in add_context\n",
      "    output_value = func(*args, **kwargs)\n",
      "  File \"<ipython-input-41-d549e6c83915>\", line 15, in update_output_div\n",
      "    return 'You entered \"{ }\"'.format( input_value)\n",
      "KeyError: ' '\n",
      "127.0.0.1 - - [09/Nov/2018 17:44:07] \"POST /_dash-update-component HTTP/1.1\" 500 -\n",
      "[2018-11-09 17:44:07,281] ERROR in app: Exception on /_dash-update-component [POST]\n",
      "Traceback (most recent call last):\n",
      "  File \"C:\\Users\\BILHA\\Anaconda3\\lib\\site-packages\\flask\\app.py\", line 1982, in wsgi_app\n",
      "    response = self.full_dispatch_request()\n",
      "  File \"C:\\Users\\BILHA\\Anaconda3\\lib\\site-packages\\flask\\app.py\", line 1614, in full_dispatch_request\n",
      "    rv = self.handle_user_exception(e)\n",
      "  File \"C:\\Users\\BILHA\\Anaconda3\\lib\\site-packages\\flask\\app.py\", line 1517, in handle_user_exception\n",
      "    reraise(exc_type, exc_value, tb)\n",
      "  File \"C:\\Users\\BILHA\\Anaconda3\\lib\\site-packages\\flask\\_compat.py\", line 33, in reraise\n",
      "    raise value\n",
      "  File \"C:\\Users\\BILHA\\Anaconda3\\lib\\site-packages\\flask\\app.py\", line 1612, in full_dispatch_request\n",
      "    rv = self.dispatch_request()\n",
      "  File \"C:\\Users\\BILHA\\Anaconda3\\lib\\site-packages\\flask\\app.py\", line 1598, in dispatch_request\n",
      "    return self.view_functions[rule.endpoint](**req.view_args)\n",
      "  File \"C:\\Users\\BILHA\\Anaconda3\\lib\\site-packages\\dash\\dash.py\", line 915, in dispatch\n",
      "    return self.callback_map[target_id]['callback'](*args)\n",
      "  File \"C:\\Users\\BILHA\\Anaconda3\\lib\\site-packages\\dash\\dash.py\", line 855, in add_context\n",
      "    output_value = func(*args, **kwargs)\n",
      "  File \"<ipython-input-41-d549e6c83915>\", line 15, in update_output_div\n",
      "    return 'You entered \"{ }\"'.format( input_value)\n",
      "KeyError: ' '\n",
      "127.0.0.1 - - [09/Nov/2018 17:44:07] \"POST /_dash-update-component HTTP/1.1\" 500 -\n",
      "[2018-11-09 17:44:07,625] ERROR in app: Exception on /_dash-update-component [POST]\n",
      "Traceback (most recent call last):\n",
      "  File \"C:\\Users\\BILHA\\Anaconda3\\lib\\site-packages\\flask\\app.py\", line 1982, in wsgi_app\n",
      "    response = self.full_dispatch_request()\n",
      "  File \"C:\\Users\\BILHA\\Anaconda3\\lib\\site-packages\\flask\\app.py\", line 1614, in full_dispatch_request\n",
      "    rv = self.handle_user_exception(e)\n",
      "  File \"C:\\Users\\BILHA\\Anaconda3\\lib\\site-packages\\flask\\app.py\", line 1517, in handle_user_exception\n",
      "    reraise(exc_type, exc_value, tb)\n",
      "  File \"C:\\Users\\BILHA\\Anaconda3\\lib\\site-packages\\flask\\_compat.py\", line 33, in reraise\n",
      "    raise value\n",
      "  File \"C:\\Users\\BILHA\\Anaconda3\\lib\\site-packages\\flask\\app.py\", line 1612, in full_dispatch_request\n",
      "    rv = self.dispatch_request()\n",
      "  File \"C:\\Users\\BILHA\\Anaconda3\\lib\\site-packages\\flask\\app.py\", line 1598, in dispatch_request\n",
      "    return self.view_functions[rule.endpoint](**req.view_args)\n",
      "  File \"C:\\Users\\BILHA\\Anaconda3\\lib\\site-packages\\dash\\dash.py\", line 915, in dispatch\n",
      "    return self.callback_map[target_id]['callback'](*args)\n",
      "  File \"C:\\Users\\BILHA\\Anaconda3\\lib\\site-packages\\dash\\dash.py\", line 855, in add_context\n",
      "    output_value = func(*args, **kwargs)\n",
      "  File \"<ipython-input-41-d549e6c83915>\", line 15, in update_output_div\n",
      "    return 'You entered \"{ }\"'.format( input_value)\n",
      "KeyError: ' '\n"
     ]
    },
    {
     "name": "stderr",
     "output_type": "stream",
     "text": [
      "127.0.0.1 - - [09/Nov/2018 17:44:07] \"POST /_dash-update-component HTTP/1.1\" 500 -\n",
      "[2018-11-09 17:44:07,806] ERROR in app: Exception on /_dash-update-component [POST]\n",
      "Traceback (most recent call last):\n",
      "  File \"C:\\Users\\BILHA\\Anaconda3\\lib\\site-packages\\flask\\app.py\", line 1982, in wsgi_app\n",
      "    response = self.full_dispatch_request()\n",
      "  File \"C:\\Users\\BILHA\\Anaconda3\\lib\\site-packages\\flask\\app.py\", line 1614, in full_dispatch_request\n",
      "    rv = self.handle_user_exception(e)\n",
      "  File \"C:\\Users\\BILHA\\Anaconda3\\lib\\site-packages\\flask\\app.py\", line 1517, in handle_user_exception\n",
      "    reraise(exc_type, exc_value, tb)\n",
      "  File \"C:\\Users\\BILHA\\Anaconda3\\lib\\site-packages\\flask\\_compat.py\", line 33, in reraise\n",
      "    raise value\n",
      "  File \"C:\\Users\\BILHA\\Anaconda3\\lib\\site-packages\\flask\\app.py\", line 1612, in full_dispatch_request\n",
      "    rv = self.dispatch_request()\n",
      "  File \"C:\\Users\\BILHA\\Anaconda3\\lib\\site-packages\\flask\\app.py\", line 1598, in dispatch_request\n",
      "    return self.view_functions[rule.endpoint](**req.view_args)\n",
      "  File \"C:\\Users\\BILHA\\Anaconda3\\lib\\site-packages\\dash\\dash.py\", line 915, in dispatch\n",
      "    return self.callback_map[target_id]['callback'](*args)\n",
      "  File \"C:\\Users\\BILHA\\Anaconda3\\lib\\site-packages\\dash\\dash.py\", line 855, in add_context\n",
      "    output_value = func(*args, **kwargs)\n",
      "  File \"<ipython-input-41-d549e6c83915>\", line 15, in update_output_div\n",
      "    return 'You entered \"{ }\"'.format( input_value)\n",
      "KeyError: ' '\n",
      "127.0.0.1 - - [09/Nov/2018 17:44:07] \"POST /_dash-update-component HTTP/1.1\" 500 -\n",
      "[2018-11-09 17:44:08,128] ERROR in app: Exception on /_dash-update-component [POST]\n",
      "Traceback (most recent call last):\n",
      "  File \"C:\\Users\\BILHA\\Anaconda3\\lib\\site-packages\\flask\\app.py\", line 1982, in wsgi_app\n",
      "    response = self.full_dispatch_request()\n",
      "  File \"C:\\Users\\BILHA\\Anaconda3\\lib\\site-packages\\flask\\app.py\", line 1614, in full_dispatch_request\n",
      "    rv = self.handle_user_exception(e)\n",
      "  File \"C:\\Users\\BILHA\\Anaconda3\\lib\\site-packages\\flask\\app.py\", line 1517, in handle_user_exception\n",
      "    reraise(exc_type, exc_value, tb)\n",
      "  File \"C:\\Users\\BILHA\\Anaconda3\\lib\\site-packages\\flask\\_compat.py\", line 33, in reraise\n",
      "    raise value\n",
      "  File \"C:\\Users\\BILHA\\Anaconda3\\lib\\site-packages\\flask\\app.py\", line 1612, in full_dispatch_request\n",
      "    rv = self.dispatch_request()\n",
      "  File \"C:\\Users\\BILHA\\Anaconda3\\lib\\site-packages\\flask\\app.py\", line 1598, in dispatch_request\n",
      "    return self.view_functions[rule.endpoint](**req.view_args)\n",
      "  File \"C:\\Users\\BILHA\\Anaconda3\\lib\\site-packages\\dash\\dash.py\", line 915, in dispatch\n",
      "    return self.callback_map[target_id]['callback'](*args)\n",
      "  File \"C:\\Users\\BILHA\\Anaconda3\\lib\\site-packages\\dash\\dash.py\", line 855, in add_context\n",
      "    output_value = func(*args, **kwargs)\n",
      "  File \"<ipython-input-41-d549e6c83915>\", line 15, in update_output_div\n",
      "    return 'You entered \"{ }\"'.format( input_value)\n",
      "KeyError: ' '\n",
      "127.0.0.1 - - [09/Nov/2018 17:44:08] \"POST /_dash-update-component HTTP/1.1\" 500 -\n",
      "[2018-11-09 17:44:08,439] ERROR in app: Exception on /_dash-update-component [POST]\n",
      "Traceback (most recent call last):\n",
      "  File \"C:\\Users\\BILHA\\Anaconda3\\lib\\site-packages\\flask\\app.py\", line 1982, in wsgi_app\n",
      "    response = self.full_dispatch_request()\n",
      "  File \"C:\\Users\\BILHA\\Anaconda3\\lib\\site-packages\\flask\\app.py\", line 1614, in full_dispatch_request\n",
      "    rv = self.handle_user_exception(e)\n",
      "  File \"C:\\Users\\BILHA\\Anaconda3\\lib\\site-packages\\flask\\app.py\", line 1517, in handle_user_exception\n",
      "    reraise(exc_type, exc_value, tb)\n",
      "  File \"C:\\Users\\BILHA\\Anaconda3\\lib\\site-packages\\flask\\_compat.py\", line 33, in reraise\n",
      "    raise value\n",
      "  File \"C:\\Users\\BILHA\\Anaconda3\\lib\\site-packages\\flask\\app.py\", line 1612, in full_dispatch_request\n",
      "    rv = self.dispatch_request()\n",
      "  File \"C:\\Users\\BILHA\\Anaconda3\\lib\\site-packages\\flask\\app.py\", line 1598, in dispatch_request\n",
      "    return self.view_functions[rule.endpoint](**req.view_args)\n",
      "  File \"C:\\Users\\BILHA\\Anaconda3\\lib\\site-packages\\dash\\dash.py\", line 915, in dispatch\n",
      "    return self.callback_map[target_id]['callback'](*args)\n",
      "  File \"C:\\Users\\BILHA\\Anaconda3\\lib\\site-packages\\dash\\dash.py\", line 855, in add_context\n",
      "    output_value = func(*args, **kwargs)\n",
      "  File \"<ipython-input-41-d549e6c83915>\", line 15, in update_output_div\n",
      "    return 'You entered \"{ }\"'.format( input_value)\n",
      "KeyError: ' '\n",
      "127.0.0.1 - - [09/Nov/2018 17:44:08] \"POST /_dash-update-component HTTP/1.1\" 500 -\n",
      "[2018-11-09 17:44:08,612] ERROR in app: Exception on /_dash-update-component [POST]\n",
      "Traceback (most recent call last):\n",
      "  File \"C:\\Users\\BILHA\\Anaconda3\\lib\\site-packages\\flask\\app.py\", line 1982, in wsgi_app\n",
      "    response = self.full_dispatch_request()\n",
      "  File \"C:\\Users\\BILHA\\Anaconda3\\lib\\site-packages\\flask\\app.py\", line 1614, in full_dispatch_request\n",
      "    rv = self.handle_user_exception(e)\n",
      "  File \"C:\\Users\\BILHA\\Anaconda3\\lib\\site-packages\\flask\\app.py\", line 1517, in handle_user_exception\n",
      "    reraise(exc_type, exc_value, tb)\n",
      "  File \"C:\\Users\\BILHA\\Anaconda3\\lib\\site-packages\\flask\\_compat.py\", line 33, in reraise\n",
      "    raise value\n",
      "  File \"C:\\Users\\BILHA\\Anaconda3\\lib\\site-packages\\flask\\app.py\", line 1612, in full_dispatch_request\n",
      "    rv = self.dispatch_request()\n",
      "  File \"C:\\Users\\BILHA\\Anaconda3\\lib\\site-packages\\flask\\app.py\", line 1598, in dispatch_request\n",
      "    return self.view_functions[rule.endpoint](**req.view_args)\n",
      "  File \"C:\\Users\\BILHA\\Anaconda3\\lib\\site-packages\\dash\\dash.py\", line 915, in dispatch\n",
      "    return self.callback_map[target_id]['callback'](*args)\n",
      "  File \"C:\\Users\\BILHA\\Anaconda3\\lib\\site-packages\\dash\\dash.py\", line 855, in add_context\n",
      "    output_value = func(*args, **kwargs)\n",
      "  File \"<ipython-input-41-d549e6c83915>\", line 15, in update_output_div\n",
      "    return 'You entered \"{ }\"'.format( input_value)\n",
      "KeyError: ' '\n",
      "127.0.0.1 - - [09/Nov/2018 17:44:08] \"POST /_dash-update-component HTTP/1.1\" 500 -\n",
      "[2018-11-09 17:44:08,768] ERROR in app: Exception on /_dash-update-component [POST]\n",
      "Traceback (most recent call last):\n",
      "  File \"C:\\Users\\BILHA\\Anaconda3\\lib\\site-packages\\flask\\app.py\", line 1982, in wsgi_app\n",
      "    response = self.full_dispatch_request()\n",
      "  File \"C:\\Users\\BILHA\\Anaconda3\\lib\\site-packages\\flask\\app.py\", line 1614, in full_dispatch_request\n",
      "    rv = self.handle_user_exception(e)\n",
      "  File \"C:\\Users\\BILHA\\Anaconda3\\lib\\site-packages\\flask\\app.py\", line 1517, in handle_user_exception\n",
      "    reraise(exc_type, exc_value, tb)\n",
      "  File \"C:\\Users\\BILHA\\Anaconda3\\lib\\site-packages\\flask\\_compat.py\", line 33, in reraise\n",
      "    raise value\n",
      "  File \"C:\\Users\\BILHA\\Anaconda3\\lib\\site-packages\\flask\\app.py\", line 1612, in full_dispatch_request\n",
      "    rv = self.dispatch_request()\n",
      "  File \"C:\\Users\\BILHA\\Anaconda3\\lib\\site-packages\\flask\\app.py\", line 1598, in dispatch_request\n",
      "    return self.view_functions[rule.endpoint](**req.view_args)\n",
      "  File \"C:\\Users\\BILHA\\Anaconda3\\lib\\site-packages\\dash\\dash.py\", line 915, in dispatch\n",
      "    return self.callback_map[target_id]['callback'](*args)\n",
      "  File \"C:\\Users\\BILHA\\Anaconda3\\lib\\site-packages\\dash\\dash.py\", line 855, in add_context\n",
      "    output_value = func(*args, **kwargs)\n",
      "  File \"<ipython-input-41-d549e6c83915>\", line 15, in update_output_div\n",
      "    return 'You entered \"{ }\"'.format( input_value)\n",
      "KeyError: ' '\n",
      "127.0.0.1 - - [09/Nov/2018 17:44:08] \"POST /_dash-update-component HTTP/1.1\" 500 -\n",
      "[2018-11-09 17:44:08,845] ERROR in app: Exception on /_dash-update-component [POST]\n",
      "Traceback (most recent call last):\n",
      "  File \"C:\\Users\\BILHA\\Anaconda3\\lib\\site-packages\\flask\\app.py\", line 1982, in wsgi_app\n",
      "    response = self.full_dispatch_request()\n",
      "  File \"C:\\Users\\BILHA\\Anaconda3\\lib\\site-packages\\flask\\app.py\", line 1614, in full_dispatch_request\n",
      "    rv = self.handle_user_exception(e)\n",
      "  File \"C:\\Users\\BILHA\\Anaconda3\\lib\\site-packages\\flask\\app.py\", line 1517, in handle_user_exception\n",
      "    reraise(exc_type, exc_value, tb)\n",
      "  File \"C:\\Users\\BILHA\\Anaconda3\\lib\\site-packages\\flask\\_compat.py\", line 33, in reraise\n",
      "    raise value\n",
      "  File \"C:\\Users\\BILHA\\Anaconda3\\lib\\site-packages\\flask\\app.py\", line 1612, in full_dispatch_request\n",
      "    rv = self.dispatch_request()\n",
      "  File \"C:\\Users\\BILHA\\Anaconda3\\lib\\site-packages\\flask\\app.py\", line 1598, in dispatch_request\n",
      "    return self.view_functions[rule.endpoint](**req.view_args)\n",
      "  File \"C:\\Users\\BILHA\\Anaconda3\\lib\\site-packages\\dash\\dash.py\", line 915, in dispatch\n",
      "    return self.callback_map[target_id]['callback'](*args)\n",
      "  File \"C:\\Users\\BILHA\\Anaconda3\\lib\\site-packages\\dash\\dash.py\", line 855, in add_context\n",
      "    output_value = func(*args, **kwargs)\n",
      "  File \"<ipython-input-41-d549e6c83915>\", line 15, in update_output_div\n",
      "    return 'You entered \"{ }\"'.format( input_value)\n",
      "KeyError: ' '\n"
     ]
    },
    {
     "name": "stderr",
     "output_type": "stream",
     "text": [
      "127.0.0.1 - - [09/Nov/2018 17:44:08] \"POST /_dash-update-component HTTP/1.1\" 500 -\n",
      "[2018-11-09 17:44:08,965] ERROR in app: Exception on /_dash-update-component [POST]\n",
      "Traceback (most recent call last):\n",
      "  File \"C:\\Users\\BILHA\\Anaconda3\\lib\\site-packages\\flask\\app.py\", line 1982, in wsgi_app\n",
      "    response = self.full_dispatch_request()\n",
      "  File \"C:\\Users\\BILHA\\Anaconda3\\lib\\site-packages\\flask\\app.py\", line 1614, in full_dispatch_request\n",
      "    rv = self.handle_user_exception(e)\n",
      "  File \"C:\\Users\\BILHA\\Anaconda3\\lib\\site-packages\\flask\\app.py\", line 1517, in handle_user_exception\n",
      "    reraise(exc_type, exc_value, tb)\n",
      "  File \"C:\\Users\\BILHA\\Anaconda3\\lib\\site-packages\\flask\\_compat.py\", line 33, in reraise\n",
      "    raise value\n",
      "  File \"C:\\Users\\BILHA\\Anaconda3\\lib\\site-packages\\flask\\app.py\", line 1612, in full_dispatch_request\n",
      "    rv = self.dispatch_request()\n",
      "  File \"C:\\Users\\BILHA\\Anaconda3\\lib\\site-packages\\flask\\app.py\", line 1598, in dispatch_request\n",
      "    return self.view_functions[rule.endpoint](**req.view_args)\n",
      "  File \"C:\\Users\\BILHA\\Anaconda3\\lib\\site-packages\\dash\\dash.py\", line 915, in dispatch\n",
      "    return self.callback_map[target_id]['callback'](*args)\n",
      "  File \"C:\\Users\\BILHA\\Anaconda3\\lib\\site-packages\\dash\\dash.py\", line 855, in add_context\n",
      "    output_value = func(*args, **kwargs)\n",
      "  File \"<ipython-input-41-d549e6c83915>\", line 15, in update_output_div\n",
      "    return 'You entered \"{ }\"'.format( input_value)\n",
      "KeyError: ' '\n",
      "127.0.0.1 - - [09/Nov/2018 17:44:08] \"POST /_dash-update-component HTTP/1.1\" 500 -\n",
      "[2018-11-09 17:44:09,096] ERROR in app: Exception on /_dash-update-component [POST]\n",
      "Traceback (most recent call last):\n",
      "  File \"C:\\Users\\BILHA\\Anaconda3\\lib\\site-packages\\flask\\app.py\", line 1982, in wsgi_app\n",
      "    response = self.full_dispatch_request()\n",
      "  File \"C:\\Users\\BILHA\\Anaconda3\\lib\\site-packages\\flask\\app.py\", line 1614, in full_dispatch_request\n",
      "    rv = self.handle_user_exception(e)\n",
      "  File \"C:\\Users\\BILHA\\Anaconda3\\lib\\site-packages\\flask\\app.py\", line 1517, in handle_user_exception\n",
      "    reraise(exc_type, exc_value, tb)\n",
      "  File \"C:\\Users\\BILHA\\Anaconda3\\lib\\site-packages\\flask\\_compat.py\", line 33, in reraise\n",
      "    raise value\n",
      "  File \"C:\\Users\\BILHA\\Anaconda3\\lib\\site-packages\\flask\\app.py\", line 1612, in full_dispatch_request\n",
      "    rv = self.dispatch_request()\n",
      "  File \"C:\\Users\\BILHA\\Anaconda3\\lib\\site-packages\\flask\\app.py\", line 1598, in dispatch_request\n",
      "    return self.view_functions[rule.endpoint](**req.view_args)\n",
      "  File \"C:\\Users\\BILHA\\Anaconda3\\lib\\site-packages\\dash\\dash.py\", line 915, in dispatch\n",
      "    return self.callback_map[target_id]['callback'](*args)\n",
      "  File \"C:\\Users\\BILHA\\Anaconda3\\lib\\site-packages\\dash\\dash.py\", line 855, in add_context\n",
      "    output_value = func(*args, **kwargs)\n",
      "  File \"<ipython-input-41-d549e6c83915>\", line 15, in update_output_div\n",
      "    return 'You entered \"{ }\"'.format( input_value)\n",
      "KeyError: ' '\n",
      "127.0.0.1 - - [09/Nov/2018 17:44:09] \"POST /_dash-update-component HTTP/1.1\" 500 -\n",
      "[2018-11-09 17:44:10,124] ERROR in app: Exception on /_dash-update-component [POST]\n",
      "Traceback (most recent call last):\n",
      "  File \"C:\\Users\\BILHA\\Anaconda3\\lib\\site-packages\\flask\\app.py\", line 1982, in wsgi_app\n",
      "    response = self.full_dispatch_request()\n",
      "  File \"C:\\Users\\BILHA\\Anaconda3\\lib\\site-packages\\flask\\app.py\", line 1614, in full_dispatch_request\n",
      "    rv = self.handle_user_exception(e)\n",
      "  File \"C:\\Users\\BILHA\\Anaconda3\\lib\\site-packages\\flask\\app.py\", line 1517, in handle_user_exception\n",
      "    reraise(exc_type, exc_value, tb)\n",
      "  File \"C:\\Users\\BILHA\\Anaconda3\\lib\\site-packages\\flask\\_compat.py\", line 33, in reraise\n",
      "    raise value\n",
      "  File \"C:\\Users\\BILHA\\Anaconda3\\lib\\site-packages\\flask\\app.py\", line 1612, in full_dispatch_request\n",
      "    rv = self.dispatch_request()\n",
      "  File \"C:\\Users\\BILHA\\Anaconda3\\lib\\site-packages\\flask\\app.py\", line 1598, in dispatch_request\n",
      "    return self.view_functions[rule.endpoint](**req.view_args)\n",
      "  File \"C:\\Users\\BILHA\\Anaconda3\\lib\\site-packages\\dash\\dash.py\", line 915, in dispatch\n",
      "    return self.callback_map[target_id]['callback'](*args)\n",
      "  File \"C:\\Users\\BILHA\\Anaconda3\\lib\\site-packages\\dash\\dash.py\", line 855, in add_context\n",
      "    output_value = func(*args, **kwargs)\n",
      "  File \"<ipython-input-41-d549e6c83915>\", line 15, in update_output_div\n",
      "    return 'You entered \"{ }\"'.format( input_value)\n",
      "KeyError: ' '\n",
      "127.0.0.1 - - [09/Nov/2018 17:44:10] \"POST /_dash-update-component HTTP/1.1\" 500 -\n",
      "[2018-11-09 17:44:10,501] ERROR in app: Exception on /_dash-update-component [POST]\n",
      "Traceback (most recent call last):\n",
      "  File \"C:\\Users\\BILHA\\Anaconda3\\lib\\site-packages\\flask\\app.py\", line 1982, in wsgi_app\n",
      "    response = self.full_dispatch_request()\n",
      "  File \"C:\\Users\\BILHA\\Anaconda3\\lib\\site-packages\\flask\\app.py\", line 1614, in full_dispatch_request\n",
      "    rv = self.handle_user_exception(e)\n",
      "  File \"C:\\Users\\BILHA\\Anaconda3\\lib\\site-packages\\flask\\app.py\", line 1517, in handle_user_exception\n",
      "    reraise(exc_type, exc_value, tb)\n",
      "  File \"C:\\Users\\BILHA\\Anaconda3\\lib\\site-packages\\flask\\_compat.py\", line 33, in reraise\n",
      "    raise value\n",
      "  File \"C:\\Users\\BILHA\\Anaconda3\\lib\\site-packages\\flask\\app.py\", line 1612, in full_dispatch_request\n",
      "    rv = self.dispatch_request()\n",
      "  File \"C:\\Users\\BILHA\\Anaconda3\\lib\\site-packages\\flask\\app.py\", line 1598, in dispatch_request\n",
      "    return self.view_functions[rule.endpoint](**req.view_args)\n",
      "  File \"C:\\Users\\BILHA\\Anaconda3\\lib\\site-packages\\dash\\dash.py\", line 915, in dispatch\n",
      "    return self.callback_map[target_id]['callback'](*args)\n",
      "  File \"C:\\Users\\BILHA\\Anaconda3\\lib\\site-packages\\dash\\dash.py\", line 855, in add_context\n",
      "    output_value = func(*args, **kwargs)\n",
      "  File \"<ipython-input-41-d549e6c83915>\", line 15, in update_output_div\n",
      "    return 'You entered \"{ }\"'.format( input_value)\n",
      "KeyError: ' '\n",
      "127.0.0.1 - - [09/Nov/2018 17:44:10] \"POST /_dash-update-component HTTP/1.1\" 500 -\n",
      "[2018-11-09 17:44:10,748] ERROR in app: Exception on /_dash-update-component [POST]\n",
      "Traceback (most recent call last):\n",
      "  File \"C:\\Users\\BILHA\\Anaconda3\\lib\\site-packages\\flask\\app.py\", line 1982, in wsgi_app\n",
      "    response = self.full_dispatch_request()\n",
      "  File \"C:\\Users\\BILHA\\Anaconda3\\lib\\site-packages\\flask\\app.py\", line 1614, in full_dispatch_request\n",
      "    rv = self.handle_user_exception(e)\n",
      "  File \"C:\\Users\\BILHA\\Anaconda3\\lib\\site-packages\\flask\\app.py\", line 1517, in handle_user_exception\n",
      "    reraise(exc_type, exc_value, tb)\n",
      "  File \"C:\\Users\\BILHA\\Anaconda3\\lib\\site-packages\\flask\\_compat.py\", line 33, in reraise\n",
      "    raise value\n",
      "  File \"C:\\Users\\BILHA\\Anaconda3\\lib\\site-packages\\flask\\app.py\", line 1612, in full_dispatch_request\n",
      "    rv = self.dispatch_request()\n",
      "  File \"C:\\Users\\BILHA\\Anaconda3\\lib\\site-packages\\flask\\app.py\", line 1598, in dispatch_request\n",
      "    return self.view_functions[rule.endpoint](**req.view_args)\n",
      "  File \"C:\\Users\\BILHA\\Anaconda3\\lib\\site-packages\\dash\\dash.py\", line 915, in dispatch\n",
      "    return self.callback_map[target_id]['callback'](*args)\n",
      "  File \"C:\\Users\\BILHA\\Anaconda3\\lib\\site-packages\\dash\\dash.py\", line 855, in add_context\n",
      "    output_value = func(*args, **kwargs)\n",
      "  File \"<ipython-input-41-d549e6c83915>\", line 15, in update_output_div\n",
      "    return 'You entered \"{ }\"'.format( input_value)\n",
      "KeyError: ' '\n",
      "127.0.0.1 - - [09/Nov/2018 17:44:10] \"POST /_dash-update-component HTTP/1.1\" 500 -\n",
      "[2018-11-09 17:44:10,997] ERROR in app: Exception on /_dash-update-component [POST]\n",
      "Traceback (most recent call last):\n",
      "  File \"C:\\Users\\BILHA\\Anaconda3\\lib\\site-packages\\flask\\app.py\", line 1982, in wsgi_app\n",
      "    response = self.full_dispatch_request()\n",
      "  File \"C:\\Users\\BILHA\\Anaconda3\\lib\\site-packages\\flask\\app.py\", line 1614, in full_dispatch_request\n",
      "    rv = self.handle_user_exception(e)\n",
      "  File \"C:\\Users\\BILHA\\Anaconda3\\lib\\site-packages\\flask\\app.py\", line 1517, in handle_user_exception\n",
      "    reraise(exc_type, exc_value, tb)\n",
      "  File \"C:\\Users\\BILHA\\Anaconda3\\lib\\site-packages\\flask\\_compat.py\", line 33, in reraise\n",
      "    raise value\n",
      "  File \"C:\\Users\\BILHA\\Anaconda3\\lib\\site-packages\\flask\\app.py\", line 1612, in full_dispatch_request\n",
      "    rv = self.dispatch_request()\n",
      "  File \"C:\\Users\\BILHA\\Anaconda3\\lib\\site-packages\\flask\\app.py\", line 1598, in dispatch_request\n",
      "    return self.view_functions[rule.endpoint](**req.view_args)\n",
      "  File \"C:\\Users\\BILHA\\Anaconda3\\lib\\site-packages\\dash\\dash.py\", line 915, in dispatch\n",
      "    return self.callback_map[target_id]['callback'](*args)\n",
      "  File \"C:\\Users\\BILHA\\Anaconda3\\lib\\site-packages\\dash\\dash.py\", line 855, in add_context\n",
      "    output_value = func(*args, **kwargs)\n",
      "  File \"<ipython-input-41-d549e6c83915>\", line 15, in update_output_div\n",
      "    return 'You entered \"{ }\"'.format( input_value)\n",
      "KeyError: ' '\n"
     ]
    },
    {
     "name": "stderr",
     "output_type": "stream",
     "text": [
      "127.0.0.1 - - [09/Nov/2018 17:44:11] \"POST /_dash-update-component HTTP/1.1\" 500 -\n",
      "[2018-11-09 17:44:11,264] ERROR in app: Exception on /_dash-update-component [POST]\n",
      "Traceback (most recent call last):\n",
      "  File \"C:\\Users\\BILHA\\Anaconda3\\lib\\site-packages\\flask\\app.py\", line 1982, in wsgi_app\n",
      "    response = self.full_dispatch_request()\n",
      "  File \"C:\\Users\\BILHA\\Anaconda3\\lib\\site-packages\\flask\\app.py\", line 1614, in full_dispatch_request\n",
      "    rv = self.handle_user_exception(e)\n",
      "  File \"C:\\Users\\BILHA\\Anaconda3\\lib\\site-packages\\flask\\app.py\", line 1517, in handle_user_exception\n",
      "    reraise(exc_type, exc_value, tb)\n",
      "  File \"C:\\Users\\BILHA\\Anaconda3\\lib\\site-packages\\flask\\_compat.py\", line 33, in reraise\n",
      "    raise value\n",
      "  File \"C:\\Users\\BILHA\\Anaconda3\\lib\\site-packages\\flask\\app.py\", line 1612, in full_dispatch_request\n",
      "    rv = self.dispatch_request()\n",
      "  File \"C:\\Users\\BILHA\\Anaconda3\\lib\\site-packages\\flask\\app.py\", line 1598, in dispatch_request\n",
      "    return self.view_functions[rule.endpoint](**req.view_args)\n",
      "  File \"C:\\Users\\BILHA\\Anaconda3\\lib\\site-packages\\dash\\dash.py\", line 915, in dispatch\n",
      "    return self.callback_map[target_id]['callback'](*args)\n",
      "  File \"C:\\Users\\BILHA\\Anaconda3\\lib\\site-packages\\dash\\dash.py\", line 855, in add_context\n",
      "    output_value = func(*args, **kwargs)\n",
      "  File \"<ipython-input-41-d549e6c83915>\", line 15, in update_output_div\n",
      "    return 'You entered \"{ }\"'.format( input_value)\n",
      "KeyError: ' '\n",
      "127.0.0.1 - - [09/Nov/2018 17:44:11] \"POST /_dash-update-component HTTP/1.1\" 500 -\n",
      "[2018-11-09 17:44:11,523] ERROR in app: Exception on /_dash-update-component [POST]\n",
      "Traceback (most recent call last):\n",
      "  File \"C:\\Users\\BILHA\\Anaconda3\\lib\\site-packages\\flask\\app.py\", line 1982, in wsgi_app\n",
      "    response = self.full_dispatch_request()\n",
      "  File \"C:\\Users\\BILHA\\Anaconda3\\lib\\site-packages\\flask\\app.py\", line 1614, in full_dispatch_request\n",
      "    rv = self.handle_user_exception(e)\n",
      "  File \"C:\\Users\\BILHA\\Anaconda3\\lib\\site-packages\\flask\\app.py\", line 1517, in handle_user_exception\n",
      "    reraise(exc_type, exc_value, tb)\n",
      "  File \"C:\\Users\\BILHA\\Anaconda3\\lib\\site-packages\\flask\\_compat.py\", line 33, in reraise\n",
      "    raise value\n",
      "  File \"C:\\Users\\BILHA\\Anaconda3\\lib\\site-packages\\flask\\app.py\", line 1612, in full_dispatch_request\n",
      "    rv = self.dispatch_request()\n",
      "  File \"C:\\Users\\BILHA\\Anaconda3\\lib\\site-packages\\flask\\app.py\", line 1598, in dispatch_request\n",
      "    return self.view_functions[rule.endpoint](**req.view_args)\n",
      "  File \"C:\\Users\\BILHA\\Anaconda3\\lib\\site-packages\\dash\\dash.py\", line 915, in dispatch\n",
      "    return self.callback_map[target_id]['callback'](*args)\n",
      "  File \"C:\\Users\\BILHA\\Anaconda3\\lib\\site-packages\\dash\\dash.py\", line 855, in add_context\n",
      "    output_value = func(*args, **kwargs)\n",
      "  File \"<ipython-input-41-d549e6c83915>\", line 15, in update_output_div\n",
      "    return 'You entered \"{ }\"'.format( input_value)\n",
      "KeyError: ' '\n",
      "127.0.0.1 - - [09/Nov/2018 17:44:11] \"POST /_dash-update-component HTTP/1.1\" 500 -\n",
      "[2018-11-09 17:44:11,843] ERROR in app: Exception on /_dash-update-component [POST]\n",
      "Traceback (most recent call last):\n",
      "  File \"C:\\Users\\BILHA\\Anaconda3\\lib\\site-packages\\flask\\app.py\", line 1982, in wsgi_app\n",
      "    response = self.full_dispatch_request()\n",
      "  File \"C:\\Users\\BILHA\\Anaconda3\\lib\\site-packages\\flask\\app.py\", line 1614, in full_dispatch_request\n",
      "    rv = self.handle_user_exception(e)\n",
      "  File \"C:\\Users\\BILHA\\Anaconda3\\lib\\site-packages\\flask\\app.py\", line 1517, in handle_user_exception\n",
      "    reraise(exc_type, exc_value, tb)\n",
      "  File \"C:\\Users\\BILHA\\Anaconda3\\lib\\site-packages\\flask\\_compat.py\", line 33, in reraise\n",
      "    raise value\n",
      "  File \"C:\\Users\\BILHA\\Anaconda3\\lib\\site-packages\\flask\\app.py\", line 1612, in full_dispatch_request\n",
      "    rv = self.dispatch_request()\n",
      "  File \"C:\\Users\\BILHA\\Anaconda3\\lib\\site-packages\\flask\\app.py\", line 1598, in dispatch_request\n",
      "    return self.view_functions[rule.endpoint](**req.view_args)\n",
      "  File \"C:\\Users\\BILHA\\Anaconda3\\lib\\site-packages\\dash\\dash.py\", line 915, in dispatch\n",
      "    return self.callback_map[target_id]['callback'](*args)\n",
      "  File \"C:\\Users\\BILHA\\Anaconda3\\lib\\site-packages\\dash\\dash.py\", line 855, in add_context\n",
      "    output_value = func(*args, **kwargs)\n",
      "  File \"<ipython-input-41-d549e6c83915>\", line 15, in update_output_div\n",
      "    return 'You entered \"{ }\"'.format( input_value)\n",
      "KeyError: ' '\n",
      "127.0.0.1 - - [09/Nov/2018 17:44:11] \"POST /_dash-update-component HTTP/1.1\" 500 -\n",
      "[2018-11-09 17:44:12,552] ERROR in app: Exception on /_dash-update-component [POST]\n",
      "Traceback (most recent call last):\n",
      "  File \"C:\\Users\\BILHA\\Anaconda3\\lib\\site-packages\\flask\\app.py\", line 1982, in wsgi_app\n",
      "    response = self.full_dispatch_request()\n",
      "  File \"C:\\Users\\BILHA\\Anaconda3\\lib\\site-packages\\flask\\app.py\", line 1614, in full_dispatch_request\n",
      "    rv = self.handle_user_exception(e)\n",
      "  File \"C:\\Users\\BILHA\\Anaconda3\\lib\\site-packages\\flask\\app.py\", line 1517, in handle_user_exception\n",
      "    reraise(exc_type, exc_value, tb)\n",
      "  File \"C:\\Users\\BILHA\\Anaconda3\\lib\\site-packages\\flask\\_compat.py\", line 33, in reraise\n",
      "    raise value\n",
      "  File \"C:\\Users\\BILHA\\Anaconda3\\lib\\site-packages\\flask\\app.py\", line 1612, in full_dispatch_request\n",
      "    rv = self.dispatch_request()\n",
      "  File \"C:\\Users\\BILHA\\Anaconda3\\lib\\site-packages\\flask\\app.py\", line 1598, in dispatch_request\n",
      "    return self.view_functions[rule.endpoint](**req.view_args)\n",
      "  File \"C:\\Users\\BILHA\\Anaconda3\\lib\\site-packages\\dash\\dash.py\", line 915, in dispatch\n",
      "    return self.callback_map[target_id]['callback'](*args)\n",
      "  File \"C:\\Users\\BILHA\\Anaconda3\\lib\\site-packages\\dash\\dash.py\", line 855, in add_context\n",
      "    output_value = func(*args, **kwargs)\n",
      "  File \"<ipython-input-41-d549e6c83915>\", line 15, in update_output_div\n",
      "    return 'You entered \"{ }\"'.format( input_value)\n",
      "KeyError: ' '\n",
      "127.0.0.1 - - [09/Nov/2018 17:44:12] \"POST /_dash-update-component HTTP/1.1\" 500 -\n",
      "[2018-11-09 17:44:12,816] ERROR in app: Exception on /_dash-update-component [POST]\n",
      "Traceback (most recent call last):\n",
      "  File \"C:\\Users\\BILHA\\Anaconda3\\lib\\site-packages\\flask\\app.py\", line 1982, in wsgi_app\n",
      "    response = self.full_dispatch_request()\n",
      "  File \"C:\\Users\\BILHA\\Anaconda3\\lib\\site-packages\\flask\\app.py\", line 1614, in full_dispatch_request\n",
      "    rv = self.handle_user_exception(e)\n",
      "  File \"C:\\Users\\BILHA\\Anaconda3\\lib\\site-packages\\flask\\app.py\", line 1517, in handle_user_exception\n",
      "    reraise(exc_type, exc_value, tb)\n",
      "  File \"C:\\Users\\BILHA\\Anaconda3\\lib\\site-packages\\flask\\_compat.py\", line 33, in reraise\n",
      "    raise value\n",
      "  File \"C:\\Users\\BILHA\\Anaconda3\\lib\\site-packages\\flask\\app.py\", line 1612, in full_dispatch_request\n",
      "    rv = self.dispatch_request()\n",
      "  File \"C:\\Users\\BILHA\\Anaconda3\\lib\\site-packages\\flask\\app.py\", line 1598, in dispatch_request\n",
      "    return self.view_functions[rule.endpoint](**req.view_args)\n",
      "  File \"C:\\Users\\BILHA\\Anaconda3\\lib\\site-packages\\dash\\dash.py\", line 915, in dispatch\n",
      "    return self.callback_map[target_id]['callback'](*args)\n",
      "  File \"C:\\Users\\BILHA\\Anaconda3\\lib\\site-packages\\dash\\dash.py\", line 855, in add_context\n",
      "    output_value = func(*args, **kwargs)\n",
      "  File \"<ipython-input-41-d549e6c83915>\", line 15, in update_output_div\n",
      "    return 'You entered \"{ }\"'.format( input_value)\n",
      "KeyError: ' '\n",
      "127.0.0.1 - - [09/Nov/2018 17:44:12] \"POST /_dash-update-component HTTP/1.1\" 500 -\n",
      "[2018-11-09 17:44:13,029] ERROR in app: Exception on /_dash-update-component [POST]\n",
      "Traceback (most recent call last):\n",
      "  File \"C:\\Users\\BILHA\\Anaconda3\\lib\\site-packages\\flask\\app.py\", line 1982, in wsgi_app\n",
      "    response = self.full_dispatch_request()\n",
      "  File \"C:\\Users\\BILHA\\Anaconda3\\lib\\site-packages\\flask\\app.py\", line 1614, in full_dispatch_request\n",
      "    rv = self.handle_user_exception(e)\n",
      "  File \"C:\\Users\\BILHA\\Anaconda3\\lib\\site-packages\\flask\\app.py\", line 1517, in handle_user_exception\n",
      "    reraise(exc_type, exc_value, tb)\n",
      "  File \"C:\\Users\\BILHA\\Anaconda3\\lib\\site-packages\\flask\\_compat.py\", line 33, in reraise\n",
      "    raise value\n",
      "  File \"C:\\Users\\BILHA\\Anaconda3\\lib\\site-packages\\flask\\app.py\", line 1612, in full_dispatch_request\n",
      "    rv = self.dispatch_request()\n",
      "  File \"C:\\Users\\BILHA\\Anaconda3\\lib\\site-packages\\flask\\app.py\", line 1598, in dispatch_request\n",
      "    return self.view_functions[rule.endpoint](**req.view_args)\n",
      "  File \"C:\\Users\\BILHA\\Anaconda3\\lib\\site-packages\\dash\\dash.py\", line 915, in dispatch\n",
      "    return self.callback_map[target_id]['callback'](*args)\n",
      "  File \"C:\\Users\\BILHA\\Anaconda3\\lib\\site-packages\\dash\\dash.py\", line 855, in add_context\n",
      "    output_value = func(*args, **kwargs)\n",
      "  File \"<ipython-input-41-d549e6c83915>\", line 15, in update_output_div\n",
      "    return 'You entered \"{ }\"'.format( input_value)\n"
     ]
    },
    {
     "name": "stderr",
     "output_type": "stream",
     "text": [
      "KeyError: ' '\n",
      "127.0.0.1 - - [09/Nov/2018 17:44:13] \"POST /_dash-update-component HTTP/1.1\" 500 -\n",
      "[2018-11-09 17:44:13,254] ERROR in app: Exception on /_dash-update-component [POST]\n",
      "Traceback (most recent call last):\n",
      "  File \"C:\\Users\\BILHA\\Anaconda3\\lib\\site-packages\\flask\\app.py\", line 1982, in wsgi_app\n",
      "    response = self.full_dispatch_request()\n",
      "  File \"C:\\Users\\BILHA\\Anaconda3\\lib\\site-packages\\flask\\app.py\", line 1614, in full_dispatch_request\n",
      "    rv = self.handle_user_exception(e)\n",
      "  File \"C:\\Users\\BILHA\\Anaconda3\\lib\\site-packages\\flask\\app.py\", line 1517, in handle_user_exception\n",
      "    reraise(exc_type, exc_value, tb)\n",
      "  File \"C:\\Users\\BILHA\\Anaconda3\\lib\\site-packages\\flask\\_compat.py\", line 33, in reraise\n",
      "    raise value\n",
      "  File \"C:\\Users\\BILHA\\Anaconda3\\lib\\site-packages\\flask\\app.py\", line 1612, in full_dispatch_request\n",
      "    rv = self.dispatch_request()\n",
      "  File \"C:\\Users\\BILHA\\Anaconda3\\lib\\site-packages\\flask\\app.py\", line 1598, in dispatch_request\n",
      "    return self.view_functions[rule.endpoint](**req.view_args)\n",
      "  File \"C:\\Users\\BILHA\\Anaconda3\\lib\\site-packages\\dash\\dash.py\", line 915, in dispatch\n",
      "    return self.callback_map[target_id]['callback'](*args)\n",
      "  File \"C:\\Users\\BILHA\\Anaconda3\\lib\\site-packages\\dash\\dash.py\", line 855, in add_context\n",
      "    output_value = func(*args, **kwargs)\n",
      "  File \"<ipython-input-41-d549e6c83915>\", line 15, in update_output_div\n",
      "    return 'You entered \"{ }\"'.format( input_value)\n",
      "KeyError: ' '\n",
      "127.0.0.1 - - [09/Nov/2018 17:44:13] \"POST /_dash-update-component HTTP/1.1\" 500 -\n",
      "[2018-11-09 17:44:13,671] ERROR in app: Exception on /_dash-update-component [POST]\n",
      "Traceback (most recent call last):\n",
      "  File \"C:\\Users\\BILHA\\Anaconda3\\lib\\site-packages\\flask\\app.py\", line 1982, in wsgi_app\n",
      "    response = self.full_dispatch_request()\n",
      "  File \"C:\\Users\\BILHA\\Anaconda3\\lib\\site-packages\\flask\\app.py\", line 1614, in full_dispatch_request\n",
      "    rv = self.handle_user_exception(e)\n",
      "  File \"C:\\Users\\BILHA\\Anaconda3\\lib\\site-packages\\flask\\app.py\", line 1517, in handle_user_exception\n",
      "    reraise(exc_type, exc_value, tb)\n",
      "  File \"C:\\Users\\BILHA\\Anaconda3\\lib\\site-packages\\flask\\_compat.py\", line 33, in reraise\n",
      "    raise value\n",
      "  File \"C:\\Users\\BILHA\\Anaconda3\\lib\\site-packages\\flask\\app.py\", line 1612, in full_dispatch_request\n",
      "    rv = self.dispatch_request()\n",
      "  File \"C:\\Users\\BILHA\\Anaconda3\\lib\\site-packages\\flask\\app.py\", line 1598, in dispatch_request\n",
      "    return self.view_functions[rule.endpoint](**req.view_args)\n",
      "  File \"C:\\Users\\BILHA\\Anaconda3\\lib\\site-packages\\dash\\dash.py\", line 915, in dispatch\n",
      "    return self.callback_map[target_id]['callback'](*args)\n",
      "  File \"C:\\Users\\BILHA\\Anaconda3\\lib\\site-packages\\dash\\dash.py\", line 855, in add_context\n",
      "    output_value = func(*args, **kwargs)\n",
      "  File \"<ipython-input-41-d549e6c83915>\", line 15, in update_output_div\n",
      "    return 'You entered \"{ }\"'.format( input_value)\n",
      "KeyError: ' '\n",
      "127.0.0.1 - - [09/Nov/2018 17:44:13] \"POST /_dash-update-component HTTP/1.1\" 500 -\n",
      "[2018-11-09 17:44:13,903] ERROR in app: Exception on /_dash-update-component [POST]\n",
      "Traceback (most recent call last):\n",
      "  File \"C:\\Users\\BILHA\\Anaconda3\\lib\\site-packages\\flask\\app.py\", line 1982, in wsgi_app\n",
      "    response = self.full_dispatch_request()\n",
      "  File \"C:\\Users\\BILHA\\Anaconda3\\lib\\site-packages\\flask\\app.py\", line 1614, in full_dispatch_request\n",
      "    rv = self.handle_user_exception(e)\n",
      "  File \"C:\\Users\\BILHA\\Anaconda3\\lib\\site-packages\\flask\\app.py\", line 1517, in handle_user_exception\n",
      "    reraise(exc_type, exc_value, tb)\n",
      "  File \"C:\\Users\\BILHA\\Anaconda3\\lib\\site-packages\\flask\\_compat.py\", line 33, in reraise\n",
      "    raise value\n",
      "  File \"C:\\Users\\BILHA\\Anaconda3\\lib\\site-packages\\flask\\app.py\", line 1612, in full_dispatch_request\n",
      "    rv = self.dispatch_request()\n",
      "  File \"C:\\Users\\BILHA\\Anaconda3\\lib\\site-packages\\flask\\app.py\", line 1598, in dispatch_request\n",
      "    return self.view_functions[rule.endpoint](**req.view_args)\n",
      "  File \"C:\\Users\\BILHA\\Anaconda3\\lib\\site-packages\\dash\\dash.py\", line 915, in dispatch\n",
      "    return self.callback_map[target_id]['callback'](*args)\n",
      "  File \"C:\\Users\\BILHA\\Anaconda3\\lib\\site-packages\\dash\\dash.py\", line 855, in add_context\n",
      "    output_value = func(*args, **kwargs)\n",
      "  File \"<ipython-input-41-d549e6c83915>\", line 15, in update_output_div\n",
      "    return 'You entered \"{ }\"'.format( input_value)\n",
      "KeyError: ' '\n",
      "127.0.0.1 - - [09/Nov/2018 17:44:13] \"POST /_dash-update-component HTTP/1.1\" 500 -\n",
      "[2018-11-09 17:44:15,801] ERROR in app: Exception on /_dash-update-component [POST]\n",
      "Traceback (most recent call last):\n",
      "  File \"C:\\Users\\BILHA\\Anaconda3\\lib\\site-packages\\flask\\app.py\", line 1982, in wsgi_app\n",
      "    response = self.full_dispatch_request()\n",
      "  File \"C:\\Users\\BILHA\\Anaconda3\\lib\\site-packages\\flask\\app.py\", line 1614, in full_dispatch_request\n",
      "    rv = self.handle_user_exception(e)\n",
      "  File \"C:\\Users\\BILHA\\Anaconda3\\lib\\site-packages\\flask\\app.py\", line 1517, in handle_user_exception\n",
      "    reraise(exc_type, exc_value, tb)\n",
      "  File \"C:\\Users\\BILHA\\Anaconda3\\lib\\site-packages\\flask\\_compat.py\", line 33, in reraise\n",
      "    raise value\n",
      "  File \"C:\\Users\\BILHA\\Anaconda3\\lib\\site-packages\\flask\\app.py\", line 1612, in full_dispatch_request\n",
      "    rv = self.dispatch_request()\n",
      "  File \"C:\\Users\\BILHA\\Anaconda3\\lib\\site-packages\\flask\\app.py\", line 1598, in dispatch_request\n",
      "    return self.view_functions[rule.endpoint](**req.view_args)\n",
      "  File \"C:\\Users\\BILHA\\Anaconda3\\lib\\site-packages\\dash\\dash.py\", line 915, in dispatch\n",
      "    return self.callback_map[target_id]['callback'](*args)\n",
      "  File \"C:\\Users\\BILHA\\Anaconda3\\lib\\site-packages\\dash\\dash.py\", line 855, in add_context\n",
      "    output_value = func(*args, **kwargs)\n",
      "  File \"<ipython-input-41-d549e6c83915>\", line 15, in update_output_div\n",
      "    return 'You entered \"{ }\"'.format( input_value)\n",
      "KeyError: ' '\n",
      "127.0.0.1 - - [09/Nov/2018 17:44:15] \"POST /_dash-update-component HTTP/1.1\" 500 -\n"
     ]
    }
   ],
   "source": [
    "## Now inside of Jupyter\n",
    "\n",
    "from IPython import display as disp2\n",
    "\n",
    "def show_app( app, port=9999, width=700, height=350, offline=False, in_binder=None):\n",
    "    url = \"http://localhost:%d\"%port \n",
    "    iframe = '<a href=\"{url}\" target=\"_new\">Open in new window</a><hr><iframe src=\"{url}\" width={width} height={height}></iframe>'.format(url = url, width=width, height=height) \n",
    "    disp2.display_html( iframe, raw=True)\n",
    "    return app.run_server(debug=False, host='0.0.0.0', port=port)\n",
    "\n",
    "                                                                                                                                          \n",
    "show_app( app)"
   ]
  },
  {
   "cell_type": "code",
   "execution_count": null,
   "metadata": {},
   "outputs": [],
   "source": []
  }
 ],
 "metadata": {
  "kernelspec": {
   "display_name": "Python 3",
   "language": "python",
   "name": "python3"
  },
  "language_info": {
   "codemirror_mode": {
    "name": "ipython",
    "version": 3
   },
   "file_extension": ".py",
   "mimetype": "text/x-python",
   "name": "python",
   "nbconvert_exporter": "python",
   "pygments_lexer": "ipython3",
   "version": "3.6.3"
  },
  "latex_envs": {
   "LaTeX_envs_menu_present": true,
   "autoclose": false,
   "autocomplete": true,
   "bibliofile": "biblio.bib",
   "cite_by": "apalike",
   "current_citInitial": 1,
   "eqLabelWithNumbers": true,
   "eqNumInitial": 1,
   "hotkeys": {
    "equation": "Ctrl-E",
    "itemize": "Ctrl-I"
   },
   "labels_anchors": false,
   "latex_user_defs": false,
   "report_style_numbering": false,
   "user_envs_cfg": false
  },
  "toc": {
   "nav_menu": {},
   "number_sections": true,
   "sideBar": true,
   "skip_h1_title": false,
   "title_cell": "Table of Contents",
   "title_sidebar": "Contents",
   "toc_cell": true,
   "toc_position": {},
   "toc_section_display": true,
   "toc_window_display": false
  }
 },
 "nbformat": 4,
 "nbformat_minor": 2
}
